Workbook
Name UT소: WBS!$F$77:$F$101
Name 설비소: WBS!$F$3:$F$76
Name 소방소: WBS!$F$102:$F$122

Sheet Cover
H1: 44562 | I1: 1355
B4: 일 일 공 정 보 고
B15: Date | E15: =H1+I1 -> 45917
B16: CODE | E16: M15X_PH4_041
B17: PROJECT NAME | E17: M15X Ph4 IBL PJT
B18: 공종 | E18: UT
B19: 업체명 | E19: M15X_PH4_UT_ 중원엔지니어링_UT배관공사_FAB
E20: 중원엔지니어링FAB
C25: 목 차 : | F25: 1. Daily Quantity Status
F26: 2. Daily Work Status
F27: 3. Daily Manpower Status
F28: 4. Daily Equipment Status
F29: 5. 사진대지

Sheet 1.출력인원 현황
B1: 1. 출력인원 현황
B2: =CONCATENATE("금일 작업 현황 :",TEXT(Cover!E15," YYYY-MM-DD, aaaa")) -> 금일 작업 현황 : 2025-09-17, 수요일
B3: 구분 | C3: Zone | D3: 공종 | E3: BP사 | F3: Scope | G3: 주요 작업 | J3: 전일 투입인원 [Incr.] | Q3: =CONCATENATE("전일 누적인원 [Cum.], ",TEXT(Cover!E15-1," YYYY-MM-DD, aaaa")) -> 전일 누적인원 [Cum.], 2025-09-16, 화요일 | X3: 금일 투입인원 [Incr.] | AE3: =CONCATENATE("금일 누적인원 [Cum.], ", TEXT(Cover!E15," YYYY-MM-DD, aaaa")) -> 금일 누적인원 [Cum.], 2025-09-17, 수요일
B4: PJT | D4: Dis | E4: 협력업체 | G4: =CONCATENATE("전일 작업사항 [", TEXT(Cover!E15-1, "mm/dd"), "]") -> 전일 작업사항 [09/16] | H4: =CONCATENATE("금일 작업사항 [", TEXT(Cover!E15, "mm/dd"), "]") -> 금일 작업사항 [09/17] | I4: =CONCATENATE("명일 작업사항 [", TEXT(Cover!E15+1, "mm/dd"), "]") -> 명일 작업사항 [09/18] | J4: 조출 | K4: 주간 | L4: 연장 | M4: 야간 | N4: 철야 | O4: Total | Q4: 조출 | R4: 주간 | S4: 연장 | T4: 야간 | U4: 철야 | V4: Total | X4: 조출 | Y4: 주간 | Z4: 연장 | AA4: 야간 | AB4: 철야 | AC4: Total | AE4: 조출 | AF4: 주간 | AG4: 연장 | AH4: 야간 | AI4: 철야 | AJ4: Total
B5: M15X PH4 | D5: =Cover!E18 -> UT | E5: =Cover!E16 -> M15X_PH4_041 | F5: F02 5층 SUB FAB F02 6층 AIR PLENUM F03 6층 CMP F03 7층 GANTRY | G5: 배관 양중 및 용접 작업 서포트 렉 설치 작업 | H5: PCW20 배관 양중 PCW20 배관 양중 PCW20 배관 양중 및 용접 작업 비계 설치 작업 | I5: PCW20 배관 양중 PCW20 배관 양중 PCW20 배관 양중 및 용접 작업 비계 설치 작업 | J5: 5 | K5: 23 | L5: 6 | M5: 0 | N5: 0 | O5: 34 | P5: 631 | Q5: ='2.직종별 인원현황'!G87 -> 21 | R5: ='2.직종별 인원현황'!H87 -> 214 | S5: ='2.직종별 인원현황'!I87 -> 148 | T5: ='2.직종별 인원현황'!J87 -> 0 | U5: ='2.직종별 인원현황'!K87 -> 0 | V5: ='2.직종별 인원현황'!L87 -> 383 | W5: =V5+V6 -> 3561 | X5: ='2.직종별 인원현황'!M87 -> 4 | Y5: ='2.직종별 인원현황'!N87 -> 17 | Z5: ='2.직종별 인원현황'!O87 -> 0 | AA5: ='2.직종별 인원현황'!P87 -> 0 | AB5: ='2.직종별 인원현황'!Q87 -> 0 | AC5: ='2.직종별 인원현황'!R87 -> 21 | AD5: =AC5+AC6 -> 212 | AE5: =SUM(Q5,X5) -> 25 | AF5: =SUM(R5,Y5) -> 231 | AG5: =SUM(S5,Z5) -> 148 | AH5: =SUM(T5,AA5) -> 0 | AI5: =SUM(U5,AB5) -> 0 | AJ5: =SUM(AE5:AI5) -> 404 | AK5: =SUM(AJ5:AJ6) -> 3773
E6: =Cover!E20 -> 중원엔지니어링FAB | J6: 122 | K6: 242 | L6: 233 | M6: 0 | N6: 0 | O6: 597 | Q6: ='2.직종별 인원현황'!G88 -> 307 | R6: ='2.직종별 인원현황'!H88 -> 1739 | S6: ='2.직종별 인원현황'!I88 -> 1126 | T6: ='2.직종별 인원현황'!J88 -> 6 | U6: ='2.직종별 인원현황'!K88 -> 0 | V6: ='2.직종별 인원현황'!L88 -> 3178 | X6: ='2.직종별 인원현황'!M88 -> 45 | Y6: ='2.직종별 인원현황'!N88 -> 146 | Z6: ='2.직종별 인원현황'!O88 -> 0 | AA6: ='2.직종별 인원현황'!P88 -> 0 | AB6: ='2.직종별 인원현황'!Q88 -> 0 | AC6: ='2.직종별 인원현황'!R88 -> 191 | AE6: =SUM(Q6,X6) -> 352 | AF6: =SUM(R6,Y6) -> 1885 | AG6: =SUM(S6,Z6) -> 1126 | AH6: =SUM(T6,AA6) -> 6 | AI6: =SUM(U6,AB6) -> 0 | AJ6: =SUM(AE6:AI6) -> 3369
J7: J열 이후 자동기입되므로, 별도 기재 X

Sheet 2.직종별 인원현황
B1: 2. 직종별 인원현황 | Q1: =1 -> 1
B2: =CONCATENATE("금일 작업 현황 :",TEXT(Cover!E15," YYYY-MM-DD, aaaa")) -> 금일 작업 현황 : 2025-09-17, 수요일
B3: =CONCATENATE("기능공 투입인원 현황 ",TEXT(Cover!E15,"yyyy/mm/dd")) -> 기능공 투입인원 현황 2025/09/17
B4: 공종 | C4: BP사 | F4: 직종 | G4: =CONCATENATE("전일누계 [", TEXT(Cover!E15-1, "mm/dd"), "]") -> 전일누계 [09/16] | M4: =CONCATENATE("금일투입 [", TEXT(Cover!E15, "mm/dd"), "]") -> 금일투입 [09/17] | S4: =CONCATENATE("금일누계 [", TEXT(Cover!E15, "mm/dd"), "]") -> 금일누계 [09/17]
B5: Dis | C5: 협력업체 | D5: 관리자/근로자 | E5: 기능공 | F5: [기능공] | G5: 조출 | H5: 주간 | I5: 연장 | J5: 야간 | K5: 철야 | L5: Cum. T | M5: 조출 | N5: 주간 | O5: 연장 | P5: 야간 | Q5: 철야 | R5: Incr. T | S5: 조출 | T5: 주간 | U5: 연장 | V5: 야간 | W5: 철야 | X5: Cum. T
B6: =Cover!E18 -> UT | C6: =Cover!E16 -> M15X_PH4_041 | D6: Mm01 | E6: sk01 | F6: BP소장 | G6: 7 | H6: 64 | I6: 48 | J6: 0 | K6: 0 | L6: 119 | M6: =SUMIF(표2[[직종구분]:[작업 위치_코드]],'2.직종별 인원현황'!$F6,표2[조출]) -> 1 | N6: =SUMIF(표2[[직종구분]:[작업 위치_코드]],'2.직종별 인원현황'!$F6,표2[주간]) -> 1 | O6: =SUMIF(표2[[직종구분]:[작업 위치_코드]],'2.직종별 인원현황'!$F6,표2[연장]) -> 0 | P6: =SUMIF(표2[[직종구분]:[작업 위치_코드]],'2.직종별 인원현황'!$F6,표2[야간]) -> 0 | Q6: =SUMIF(표2[[직종구분]:[작업 위치_코드]],'2.직종별 인원현황'!$F6,표2[철야]) -> 0 | R6: =SUM(M6:Q6) -> 2 | S6: =G6+M6 -> 8 | T6: =H6+N6 -> 65 | U6: =I6+O6 -> 48 | V6: =J6+P6 -> 0 | W6: =K6+Q6 -> 0 | X6: =SUM(S6:W6) -> 121
C7: =Cover!E20 -> 중원엔지니어링FAB | D7: Mm02 | E7: sk02 | F7: 공사관리자 | G7: 7 | H7: 74 | I7: 50 | J7: 0 | K7: 0 | L7: 131 | M7: =SUMIF(표2[[직종구분]:[작업 위치_코드]],'2.직종별 인원현황'!$F7,표2[조출]) -> 1 | N7: =SUMIF(표2[[직종구분]:[작업 위치_코드]],'2.직종별 인원현황'!$F7,표2[주간]) -> 5 | O7: =SUMIF(표2[[직종구분]:[작업 위치_코드]],'2.직종별 인원현황'!$F7,표2[연장]) -> 0 | P7: =SUMIF(표2[[직종구분]:[작업 위치_코드]],'2.직종별 인원현황'!$F7,표2[야간]) -> 0 | Q7: =SUMIF(표2[[직종구분]:[작업 위치_코드]],'2.직종별 인원현황'!$F7,표2[철야]) -> 0 | R7: =SUM(M7:Q7) -> 6 | S7: =G7+M7 -> 8 | T7: =H7+N7 -> 79 | U7: =I7+O7 -> 50 | V7: =J7+P7 -> 0 | W7: =K7+Q7 -> 0 | X7: =SUM(S7:W7) -> 137
D8: Mm03 | E8: sk03 | F8: 안전관리자 | G8: 7 | H8: 74 | I8: 50 | J8: 0 | K8: 0 | L8: 131 | M8: =SUMIF(표2[[직종구분]:[작업 위치_코드]],'2.직종별 인원현황'!$F8,표2[조출]) -> 2 | N8: =SUMIF(표2[[직종구분]:[작업 위치_코드]],'2.직종별 인원현황'!$F8,표2[주간]) -> 7 | O8: =SUMIF(표2[[직종구분]:[작업 위치_코드]],'2.직종별 인원현황'!$F8,표2[연장]) -> 0 | P8: =SUMIF(표2[[직종구분]:[작업 위치_코드]],'2.직종별 인원현황'!$F8,표2[야간]) -> 0 | Q8: =SUMIF(표2[[직종구분]:[작업 위치_코드]],'2.직종별 인원현황'!$F8,표2[철야]) -> 0 | R8: =SUM(M8:Q8) -> 9 | S8: =G8+M8 -> 9 | T8: =H8+N8 -> 81 | U8: =I8+O8 -> 50 | V8: =J8+P8 -> 0 | W8: =K8+Q8 -> 0 | X8: =SUM(S8:W8) -> 140
D9: Mm04 | E9: sk04 | F9: 품질관리자 | G9: 0 | H9: 2 | I9: 0 | J9: 0 | K9: 0 | L9: 2 | M9: =SUMIF(표2[[직종구분]:[작업 위치_코드]],'2.직종별 인원현황'!$F9,표2[조출]) -> 0 | N9: =SUMIF(표2[[직종구분]:[작업 위치_코드]],'2.직종별 인원현황'!$F9,표2[주간]) -> 4 | O9: =SUMIF(표2[[직종구분]:[작업 위치_코드]],'2.직종별 인원현황'!$F9,표2[연장]) -> 0 | P9: =SUMIF(표2[[직종구분]:[작업 위치_코드]],'2.직종별 인원현황'!$F9,표2[야간]) -> 0 | Q9: =SUMIF(표2[[직종구분]:[작업 위치_코드]],'2.직종별 인원현황'!$F9,표2[철야]) -> 0 | R9: =SUM(M9:Q9) -> 4 | S9: =G9+M9 -> 0 | T9: =H9+N9 -> 6 | U9: =I9+O9 -> 0 | V9: =J9+P9 -> 0 | W9: =K9+Q9 -> 0 | X9: =SUM(S9:W9) -> 6
D10: Mm05 | E10: sk05 | F10: 일반관리자 | G10: 0 | H10: 0 | I10: 0 | J10: 0 | K10: 0 | L10: 0 | M10: =SUMIF(표2[[직종구분]:[작업 위치_코드]],'2.직종별 인원현황'!$F10,표2[조출]) -> 0 | N10: =SUMIF(표2[[직종구분]:[작업 위치_코드]],'2.직종별 인원현황'!$F10,표2[주간]) -> 0 | O10: =SUMIF(표2[[직종구분]:[작업 위치_코드]],'2.직종별 인원현황'!$F10,표2[연장]) -> 0 | P10: =SUMIF(표2[[직종구분]:[작업 위치_코드]],'2.직종별 인원현황'!$F10,표2[야간]) -> 0 | Q10: =SUMIF(표2[[직종구분]:[작업 위치_코드]],'2.직종별 인원현황'!$F10,표2[철야]) -> 0 | R10: =SUM(M10:Q10) -> 0 | S10: =G10+M10 -> 0 | T10: =H10+N10 -> 0 | U10: =I10+O10 -> 0 | V10: =J10+P10 -> 0 | W10: =K10+Q10 -> 0 | X10: =SUM(S10:W10) -> 0
D11: Mm06 | E11: sk06 | F11: Shop설계 | G11: 0 | H11: 0 | I11: 0 | J11: 0 | K11: 0 | L11: 0 | M11: =SUMIF(표2[[직종구분]:[작업 위치_코드]],'2.직종별 인원현황'!$F11,표2[조출]) -> 0 | N11: =SUMIF(표2[[직종구분]:[작업 위치_코드]],'2.직종별 인원현황'!$F11,표2[주간]) -> 0 | O11: =SUMIF(표2[[직종구분]:[작업 위치_코드]],'2.직종별 인원현황'!$F11,표2[연장]) -> 0 | P11: =SUMIF(표2[[직종구분]:[작업 위치_코드]],'2.직종별 인원현황'!$F11,표2[야간]) -> 0 | Q11: =SUMIF(표2[[직종구분]:[작업 위치_코드]],'2.직종별 인원현황'!$F11,표2[철야]) -> 0 | R11: =SUM(M11:Q11) -> 0 | S11: =G11+M11 -> 0 | T11: =H11+N11 -> 0 | U11: =I11+O11 -> 0 | V11: =J11+P11 -> 0 | W11: =K11+Q11 -> 0 | X11: =SUM(S11:W11) -> 0
D12: Mm07 | E12: sk07 | F12: 관리자07 | G12: 0 | H12: 0 | I12: 0 | J12: 0 | K12: 0 | L12: 0 | M12: =SUMIF(표2[[직종구분]:[작업 위치_코드]],'2.직종별 인원현황'!$F12,표2[조출]) -> 0 | N12: =SUMIF(표2[[직종구분]:[작업 위치_코드]],'2.직종별 인원현황'!$F12,표2[주간]) -> 0 | O12: =SUMIF(표2[[직종구분]:[작업 위치_코드]],'2.직종별 인원현황'!$F12,표2[연장]) -> 0 | P12: =SUMIF(표2[[직종구분]:[작업 위치_코드]],'2.직종별 인원현황'!$F12,표2[야간]) -> 0 | Q12: =SUMIF(표2[[직종구분]:[작업 위치_코드]],'2.직종별 인원현황'!$F12,표2[철야]) -> 0 | R12: =SUM(M12:Q12) -> 0 | S12: =G12+M12 -> 0 | T12: =H12+N12 -> 0 | U12: =I12+O12 -> 0 | V12: =J12+P12 -> 0 | W12: =K12+Q12 -> 0 | X12: =SUM(S12:W12) -> 0
D13: Mm08 | E13: sk08 | F13: 관리자08 | G13: 0 | H13: 0 | I13: 0 | J13: 0 | K13: 0 | L13: 0 | M13: =SUMIF(표2[[직종구분]:[작업 위치_코드]],'2.직종별 인원현황'!$F13,표2[조출]) -> 0 | N13: =SUMIF(표2[[직종구분]:[작업 위치_코드]],'2.직종별 인원현황'!$F13,표2[주간]) -> 0 | O13: =SUMIF(표2[[직종구분]:[작업 위치_코드]],'2.직종별 인원현황'!$F13,표2[연장]) -> 0 | P13: =SUMIF(표2[[직종구분]:[작업 위치_코드]],'2.직종별 인원현황'!$F13,표2[야간]) -> 0 | Q13: =SUMIF(표2[[직종구분]:[작업 위치_코드]],'2.직종별 인원현황'!$F13,표2[철야]) -> 0 | R13: =SUM(M13:Q13) -> 0 | S13: =G13+M13 -> 0 | T13: =H13+N13 -> 0 | U13: =I13+O13 -> 0 | V13: =J13+P13 -> 0 | W13: =K13+Q13 -> 0 | X13: =SUM(S13:W13) -> 0
D14: Mm09 | E14: sk09 | F14: 관리자09 | G14: 0 | H14: 0 | I14: 0 | J14: 0 | K14: 0 | L14: 0 | M14: =SUMIF(표2[[직종구분]:[작업 위치_코드]],'2.직종별 인원현황'!$F14,표2[조출]) -> 0 | N14: =SUMIF(표2[[직종구분]:[작업 위치_코드]],'2.직종별 인원현황'!$F14,표2[주간]) -> 0 | O14: =SUMIF(표2[[직종구분]:[작업 위치_코드]],'2.직종별 인원현황'!$F14,표2[연장]) -> 0 | P14: =SUMIF(표2[[직종구분]:[작업 위치_코드]],'2.직종별 인원현황'!$F14,표2[야간]) -> 0 | Q14: =SUMIF(표2[[직종구분]:[작업 위치_코드]],'2.직종별 인원현황'!$F14,표2[철야]) -> 0 | R14: =SUM(M14:Q14) -> 0 | S14: =G14+M14 -> 0 | T14: =H14+N14 -> 0 | U14: =I14+O14 -> 0 | V14: =J14+P14 -> 0 | W14: =K14+Q14 -> 0 | X14: =SUM(S14:W14) -> 0
D15: Mm10 | E15: sk10 | F15: 관리자10 | G15: 0 | H15: 0 | I15: 0 | J15: 0 | K15: 0 | L15: 0 | M15: =SUMIF(표2[[직종구분]:[작업 위치_코드]],'2.직종별 인원현황'!$F15,표2[조출]) -> 0 | N15: =SUMIF(표2[[직종구분]:[작업 위치_코드]],'2.직종별 인원현황'!$F15,표2[주간]) -> 0 | O15: =SUMIF(표2[[직종구분]:[작업 위치_코드]],'2.직종별 인원현황'!$F15,표2[연장]) -> 0 | P15: =SUMIF(표2[[직종구분]:[작업 위치_코드]],'2.직종별 인원현황'!$F15,표2[야간]) -> 0 | Q15: =SUMIF(표2[[직종구분]:[작업 위치_코드]],'2.직종별 인원현황'!$F15,표2[철야]) -> 0 | R15: =SUM(M15:Q15) -> 0 | S15: =G15+M15 -> 0 | T15: =H15+N15 -> 0 | U15: =I15+O15 -> 0 | V15: =J15+P15 -> 0 | W15: =K15+Q15 -> 0 | X15: =SUM(S15:W15) -> 0
D16: Wk01 | E16: sk06 | F16: H/C 장비기사 | G16: 0 | H16: 0 | I16: 0 | J16: 0 | K16: 0 | L16: 0 | M16: =SUMIF(표2[[직종구분]:[작업 위치_코드]],'2.직종별 인원현황'!$F16,표2[조출]) -> 0 | N16: =SUMIF(표2[[직종구분]:[작업 위치_코드]],'2.직종별 인원현황'!$F16,표2[주간]) -> 0 | O16: =SUMIF(표2[[직종구분]:[작업 위치_코드]],'2.직종별 인원현황'!$F16,표2[연장]) -> 0 | P16: =SUMIF(표2[[직종구분]:[작업 위치_코드]],'2.직종별 인원현황'!$F16,표2[야간]) -> 0 | Q16: =SUMIF(표2[[직종구분]:[작업 위치_코드]],'2.직종별 인원현황'!$F16,표2[철야]) -> 0 | R16: =SUM(M16:Q16) -> 0 | S16: =G16+M16 -> 0 | T16: =H16+N16 -> 0 | U16: =I16+O16 -> 0 | V16: =J16+P16 -> 0 | W16: =K16+Q16 -> 0 | X16: =SUM(S16:W16) -> 0
D17: Wk02 | E17: sk07 | F17: T/C 장비기사 | G17: 0 | H17: 0 | I17: 0 | J17: 0 | K17: 0 | L17: 0 | M17: =SUMIF(표2[[직종구분]:[작업 위치_코드]],'2.직종별 인원현황'!$F17,표2[조출]) -> 0 | N17: =SUMIF(표2[[직종구분]:[작업 위치_코드]],'2.직종별 인원현황'!$F17,표2[주간]) -> 0 | O17: =SUMIF(표2[[직종구분]:[작업 위치_코드]],'2.직종별 인원현황'!$F17,표2[연장]) -> 0 | P17: =SUMIF(표2[[직종구분]:[작업 위치_코드]],'2.직종별 인원현황'!$F17,표2[야간]) -> 0 | Q17: =SUMIF(표2[[직종구분]:[작업 위치_코드]],'2.직종별 인원현황'!$F17,표2[철야]) -> 0 | R17: =SUM(M17:Q17) -> 0 | S17: =G17+M17 -> 0 | T17: =H17+N17 -> 0 | U17: =I17+O17 -> 0 | V17: =J17+P17 -> 0 | W17: =K17+Q17 -> 0 | X17: =SUM(S17:W17) -> 0
D18: Wk03 | E18: sk08 | F18: T/C 정비기사 | G18: 0 | H18: 0 | I18: 0 | J18: 0 | K18: 0 | L18: 0 | M18: =SUMIF(표2[[직종구분]:[작업 위치_코드]],'2.직종별 인원현황'!$F18,표2[조출]) -> 0 | N18: =SUMIF(표2[[직종구분]:[작업 위치_코드]],'2.직종별 인원현황'!$F18,표2[주간]) -> 0 | O18: =SUMIF(표2[[직종구분]:[작업 위치_코드]],'2.직종별 인원현황'!$F18,표2[연장]) -> 0 | P18: =SUMIF(표2[[직종구분]:[작업 위치_코드]],'2.직종별 인원현황'!$F18,표2[야간]) -> 0 | Q18: =SUMIF(표2[[직종구분]:[작업 위치_코드]],'2.직종별 인원현황'!$F18,표2[철야]) -> 0 | R18: =SUM(M18:Q18) -> 0 | S18: =G18+M18 -> 0 | T18: =H18+N18 -> 0 | U18: =I18+O18 -> 0 | V18: =J18+P18 -> 0 | W18: =K18+Q18 -> 0 | X18: =SUM(S18:W18) -> 0
D19: Wk04 | E19: sk09 | F19: 스카이 장비기사 | G19: 0 | H19: 0 | I19: 0 | J19: 0 | K19: 0 | L19: 0 | M19: =SUMIF(표2[[직종구분]:[작업 위치_코드]],'2.직종별 인원현황'!$F19,표2[조출]) -> 0 | N19: =SUMIF(표2[[직종구분]:[작업 위치_코드]],'2.직종별 인원현황'!$F19,표2[주간]) -> 0 | O19: =SUMIF(표2[[직종구분]:[작업 위치_코드]],'2.직종별 인원현황'!$F19,표2[연장]) -> 0 | P19: =SUMIF(표2[[직종구분]:[작업 위치_코드]],'2.직종별 인원현황'!$F19,표2[야간]) -> 0 | Q19: =SUMIF(표2[[직종구분]:[작업 위치_코드]],'2.직종별 인원현황'!$F19,표2[철야]) -> 0 | R19: =SUM(M19:Q19) -> 0 | S19: =G19+M19 -> 0 | T19: =H19+N19 -> 0 | U19: =I19+O19 -> 0 | V19: =J19+P19 -> 0 | W19: =K19+Q19 -> 0 | X19: =SUM(S19:W19) -> 0
... D76: Wk61 | E76: sk66 | F76: 경량벽체설치 | G76: 0 | H76: 0 | I76: 0 | J76: 0 | K76: 0 | L76: 0 | M76: =SUMIF(표2[[직종구분]:[작업 위치_코드]],'2.직종별 인원현황'!$F76,표2[조출]) -> 0 | N76: =SUMIF(표2[[직종구분]:[작업 위치_코드]],'2.직종별 인원현황'!$F76,표2[주간]) -> 0 | O76: =SUMIF(표2[[직종구분]:[작업 위치_코드]],'2.직종별 인원현황'!$F76,표2[연장]) -> 0 | P76: =SUMIF(표2[[직종구분]:[작업 위치_코드]],'2.직종별 인원현황'!$F76,표2[야간]) -> 0 | Q76: =SUMIF(표2[[직종구분]:[작업 위치_코드]],'2.직종별 인원현황'!$F76,표2[철야]) -> 0 | R76: =SUM(M76:Q76) -> 0 | S76: =G76+M76 -> 0 | T76: =H76+N76 -> 0 | U76: =I76+O76 -> 0 | V76: =J76+P76 -> 0 | W76: =K76+Q76 -> 0 | X76: =SUM(S76:W76) -> 0
D77: Wk62 | E77: sk67 | F77: 경량벽체설치 | G77: 0 | H77: 0 | I77: 0 | J77: 0 | K77: 0 | M77: =SUMIF(표2[[직종구분]:[작업 위치_코드]],'2.직종별 인원현황'!$F77,표2[조출]) -> 0 | N77: =SUMIF(표2[[직종구분]:[작업 위치_코드]],'2.직종별 인원현황'!$F77,표2[주간]) -> 0 | O77: =SUMIF(표2[[직종구분]:[작업 위치_코드]],'2.직종별 인원현황'!$F77,표2[연장]) -> 0 | P77: =SUMIF(표2[[직종구분]:[작업 위치_코드]],'2.직종별 인원현황'!$F77,표2[야간]) -> 0 | Q77: =SUMIF(표2[[직종구분]:[작업 위치_코드]],'2.직종별 인원현황'!$F77,표2[철야]) -> 0 | R77: =SUM(M77:Q77) -> 0 | S77: =G77+M77 -> 0 | T77: =H77+N77 -> 0 | U77: =I77+O77 -> 0 | V77: =J77+P77 -> 0 | W77: =K77+Q77 -> 0 | X77: =SUM(S77:W77) -> 0
D78: Wk63 | E78: sk68 | F78: 인력운반공 | M78: =SUMIF(표2[[직종구분]:[작업 위치_코드]],'2.직종별 인원현황'!$F78,표2[조출]) -> 0 | N78: =SUMIF(표2[[직종구분]:[작업 위치_코드]],'2.직종별 인원현황'!$F78,표2[주간]) -> 0 | O78: =SUMIF(표2[[직종구분]:[작업 위치_코드]],'2.직종별 인원현황'!$F78,표2[연장]) -> 0 | P78: =SUMIF(표2[[직종구분]:[작업 위치_코드]],'2.직종별 인원현황'!$F78,표2[야간]) -> 0 | Q78: =SUMIF(표2[[직종구분]:[작업 위치_코드]],'2.직종별 인원현황'!$F78,표2[철야]) -> 0 | R78: =SUM(M78:Q78) -> 0 | S78: =G78+M78 -> 0 | T78: =H78+N78 -> 0 | U78: =I78+O78 -> 0 | V78: =J78+P78 -> 0 | W78: =K78+Q78 -> 0 | X78: =SUM(S78:W78) -> 0
D79: Wk64 | E79: sk69 | F79: 보통인부 | G79: 87 | H79: =551+15 -> 566 | I79: =5+346 -> 351 | J79: 6 | K79: 0 | L79: 1010 | M79: =SUMIF(표2[[직종구분]:[작업 위치_코드]],'2.직종별 인원현황'!$F79,표2[조출]) -> 19 | N79: =SUMIF(표2[[직종구분]:[작업 위치_코드]],'2.직종별 인원현황'!$F79,표2[주간]) -> 62 | O79: =SUMIF(표2[[직종구분]:[작업 위치_코드]],'2.직종별 인원현황'!$F79,표2[연장]) -> 0 | P79: =SUMIF(표2[[직종구분]:[작업 위치_코드]],'2.직종별 인원현황'!$F79,표2[야간]) -> 0 | Q79: =SUMIF(표2[[직종구분]:[작업 위치_코드]],'2.직종별 인원현황'!$F79,표2[철야]) -> 0 | R79: =SUM(M79:Q79) -> 81 | S79: =G79+M79 -> 106 | T79: =H79+N79 -> 628 | U79: =I79+O79 -> 351 | V79: =J79+P79 -> 6 | W79: =K79+Q79 -> 0 | X79: =SUM(S79:W79) -> 1091
D80: Wk65 | E80: sk70 | F80: 작업자66 | G80: 0 | H80: 0 | I80: 0 | J80: 0 | K80: 0 | L80: 0 | M80: =SUMIF(표2[[직종구분]:[작업 위치_코드]],'2.직종별 인원현황'!$F80,표2[조출]) -> 0 | N80: =SUMIF(표2[[직종구분]:[작업 위치_코드]],'2.직종별 인원현황'!$F80,표2[주간]) -> 0 | O80: =SUMIF(표2[[직종구분]:[작업 위치_코드]],'2.직종별 인원현황'!$F80,표2[연장]) -> 0 | P80: =SUMIF(표2[[직종구분]:[작업 위치_코드]],'2.직종별 인원현황'!$F80,표2[야간]) -> 0 | Q80: =SUMIF(표2[[직종구분]:[작업 위치_코드]],'2.직종별 인원현황'!$F80,표2[철야]) -> 0 | R80: =SUM(M80:Q80) -> 0 | S80: =G80+M80 -> 0 | T80: =H80+N80 -> 0 | U80: =I80+O80 -> 0 | V80: =J80+P80 -> 0 | W80: =K80+Q80 -> 0 | X80: =SUM(S80:W80) -> 0
D81: Wk66 | E81: sk71 | F81: 작업자67 | G81: 0 | H81: 0 | I81: 0 | J81: 0 | K81: 0 | L81: =SUM(G81:K81) -> 0 | M81: =SUMIF(표2[[직종구분]:[작업 위치_코드]],'2.직종별 인원현황'!$F81,표2[조출]) -> 0 | N81: =SUMIF(표2[[직종구분]:[작업 위치_코드]],'2.직종별 인원현황'!$F81,표2[주간]) -> 0 | O81: =SUMIF(표2[[직종구분]:[작업 위치_코드]],'2.직종별 인원현황'!$F81,표2[연장]) -> 0 | P81: =SUMIF(표2[[직종구분]:[작업 위치_코드]],'2.직종별 인원현황'!$F81,표2[야간]) -> 0 | Q81: =SUMIF(표2[[직종구분]:[작업 위치_코드]],'2.직종별 인원현황'!$F81,표2[철야]) -> 0 | R81: =SUM(M81:Q81) -> 0 | S81: =G81+M81 -> 0 | T81: =H81+N81 -> 0 | U81: =I81+O81 -> 0 | V81: =J81+P81 -> 0 | W81: =K81+Q81 -> 0 | X81: =SUM(S81:W81) -> 0
D82: Wk67 | E82: sk72 | F82: 작업자68 | G82: 0 | H82: 0 | I82: 0 | J82: 0 | K82: 0 | L82: =SUM(G82:K82) -> 0 | M82: =SUMIF(표2[[직종구분]:[작업 위치_코드]],'2.직종별 인원현황'!$F82,표2[조출]) -> 0 | N82: =SUMIF(표2[[직종구분]:[작업 위치_코드]],'2.직종별 인원현황'!$F82,표2[주간]) -> 0 | O82: =SUMIF(표2[[직종구분]:[작업 위치_코드]],'2.직종별 인원현황'!$F82,표2[연장]) -> 0 | P82: =SUMIF(표2[[직종구분]:[작업 위치_코드]],'2.직종별 인원현황'!$F82,표2[야간]) -> 0 | Q82: =SUMIF(표2[[직종구분]:[작업 위치_코드]],'2.직종별 인원현황'!$F82,표2[철야]) -> 0 | R82: =SUM(M82:Q82) -> 0 | S82: =G82+M82 -> 0 | T82: =H82+N82 -> 0 | U82: =I82+O82 -> 0 | V82: =J82+P82 -> 0 | W82: =K82+Q82 -> 0 | X82: =SUM(S82:W82) -> 0
D83: Wk68 | E83: sk73 | F83: 작업자69 | G83: 0 | H83: 0 | I83: 0 | J83: 0 | K83: 0 | L83: =SUM(G83:K83) -> 0 | M83: =SUMIF(표2[[직종구분]:[작업 위치_코드]],'2.직종별 인원현황'!$F83,표2[조출]) -> 0 | N83: =SUMIF(표2[[직종구분]:[작업 위치_코드]],'2.직종별 인원현황'!$F83,표2[주간]) -> 0 | O83: =SUMIF(표2[[직종구분]:[작업 위치_코드]],'2.직종별 인원현황'!$F83,표2[연장]) -> 0 | P83: =SUMIF(표2[[직종구분]:[작업 위치_코드]],'2.직종별 인원현황'!$F83,표2[야간]) -> 0 | Q83: =SUMIF(표2[[직종구분]:[작업 위치_코드]],'2.직종별 인원현황'!$F83,표2[철야]) -> 0 | R83: =SUM(M83:Q83) -> 0 | S83: =G83+M83 -> 0 | T83: =H83+N83 -> 0 | U83: =I83+O83 -> 0 | V83: =J83+P83 -> 0 | W83: =K83+Q83 -> 0 | X83: =SUM(S83:W83) -> 0
D84: Wk69 | E84: sk74 | F84: 작업자70 | G84: 0 | H84: 0 | I84: 0 | J84: 0 | K84: 0 | L84: =SUM(G84:K84) -> 0 | M84: =SUMIF(표2[[직종구분]:[작업 위치_코드]],'2.직종별 인원현황'!$F84,표2[조출]) -> 0 | N84: =SUMIF(표2[[직종구분]:[작업 위치_코드]],'2.직종별 인원현황'!$F84,표2[주간]) -> 0 | O84: =SUMIF(표2[[직종구분]:[작업 위치_코드]],'2.직종별 인원현황'!$F84,표2[연장]) -> 0 | P84: =SUMIF(표2[[직종구분]:[작업 위치_코드]],'2.직종별 인원현황'!$F84,표2[야간]) -> 0 | Q84: =SUMIF(표2[[직종구분]:[작업 위치_코드]],'2.직종별 인원현황'!$F84,표2[철야]) -> 0 | R84: =SUM(M84:Q84) -> 0 | S84: =G84+M84 -> 0 | T84: =H84+N84 -> 0 | U84: =I84+O84 -> 0 | V84: =J84+P84 -> 0 | W84: =K84+Q84 -> 0 | X84: =SUM(S84:W84) -> 0
D85: Wk70 | E85: sk75 | F85: 작업자71 | G85: 0 | H85: 0 | I85: 0 | J85: 0 | K85: 0 | L85: =SUM(G85:K85) -> 0 | M85: =SUMIF(표2[[직종구분]:[작업 위치_코드]],'2.직종별 인원현황'!$F85,표2[조출]) -> 0 | N85: =SUMIF(표2[[직종구분]:[작업 위치_코드]],'2.직종별 인원현황'!$F85,표2[주간]) -> 0 | O85: =SUMIF(표2[[직종구분]:[작업 위치_코드]],'2.직종별 인원현황'!$F85,표2[연장]) -> 0 | P85: =SUMIF(표2[[직종구분]:[작업 위치_코드]],'2.직종별 인원현황'!$F85,표2[야간]) -> 0 | Q85: =SUMIF(표2[[직종구분]:[작업 위치_코드]],'2.직종별 인원현황'!$F85,표2[철야]) -> 0 | R85: =SUM(M85:Q85) -> 0 | S85: =G85+M85 -> 0 | T85: =H85+N85 -> 0 | U85: =I85+O85 -> 0 | V85: =J85+P85 -> 0 | W85: =K85+Q85 -> 0 | X85: =SUM(S85:W85) -> 0
D86: Wk71 | E86: sk76 | F86: 작업자72 | G86: 0 | H86: 0 | I86: 0 | J86: 0 | K86: 0 | L86: =SUM(G86:K86) -> 0 | M86: =SUMIF(표2[[직종구분]:[작업 위치_코드]],'2.직종별 인원현황'!$F86,표2[조출]) -> 0 | N86: =SUMIF(표2[[직종구분]:[작업 위치_코드]],'2.직종별 인원현황'!$F86,표2[주간]) -> 0 | O86: =SUMIF(표2[[직종구분]:[작업 위치_코드]],'2.직종별 인원현황'!$F86,표2[연장]) -> 0 | P86: =SUMIF(표2[[직종구분]:[작업 위치_코드]],'2.직종별 인원현황'!$F86,표2[야간]) -> 0 | Q86: =SUMIF(표2[[직종구분]:[작업 위치_코드]],'2.직종별 인원현황'!$F86,표2[철야]) -> 0 | R86: =SUM(M86:Q86) -> 0 | S86: =G86+M86 -> 0 | T86: =H86+N86 -> 0 | U86: =I86+O86 -> 0 | V86: =J86+P86 -> 0 | W86: =K86+Q86 -> 0 | X86: =SUM(S86:W86) -> 0
B87: 관리자 | G87: =SUM(G6:G15) -> 21 | H87: =SUM(H6:H15) -> 214 | I87: =SUM(I6:I15) -> 148 | J87: =SUM(J6:J15) -> 0 | K87: =SUM(K6:K15) -> 0 | L87: =SUM(L6:L15) -> 383 | M87: =SUM(M6:M15) -> 4 | N87: =SUM(N6:N15) -> 17 | ... X87: =SUM(X6:X15) -> 404
B88: 근로자 | G88: =SUM(G16:G86) -> 307 | H88: =SUM(H16:H86) -> 1739 | I88: =SUM(I16:I86) -> 1126 | J88: =SUM(J16:J86) -> 6 | K88: =SUM(K16:K86) -> 0 | L88: =SUM(L16:L86) -> 3178 | M88: =SUM(M16:M86) -> 45 | N88: =SUM(N16:N86) -> 146 | ... X88: =SUM(X16:X86) -> 3369
F89: =CONCATENATE(B6," ",C6," ","기능공 투입 Total") -> UT M15X_PH4_041 기능공 투입 Total | G89: =SUM(G6:G86) -> 328 | H89: =SUM(H6:H86) -> 1953 | I89: =SUM(I6:I86) -> 1274 | J89: =SUM(J6:J86) -> 6 | K89: =SUM(K6:K86) -> 0 | L89: =SUM(L6:L86) -> 3561 | M89: =SUM(M6:M86) -> 49 | N89: =SUM(N6:N86) -> 163 | ... X89: =SUM(X6:X86) -> 3773

Sheet 3.장비현황
B1: 3. 장비현황
B2: =CONCATENATE("금일 작업 현황 :",TEXT(Cover!E15," YYYY-MM-DD, aaaa")) -> 금일 작업 현황 : 2025-09-17, 수요일
B3: =CONCATENATE("장비 투입인원 현황 ",TEXT(Cover!E15,"yyyy/mm/dd")) -> 장비 투입인원 현황 2025/09/17
B4: 공종 | C4: BP사 | D4: 장비 명 | G4: =CONCATENATE("전일누계 [", TEXT(Cover!E15-1, "mm/dd"), "]") -> 전일누계 [09/16] | M4: =CONCATENATE("금일투입 [", TEXT(Cover!E15, "mm/dd"), "]") -> 금일투입 [09/17] | S4: =CONCATENATE("금일누계 [", TEXT(Cover!E15, "mm/dd"), "]") -> 금일누계 [09/17]
B5: Dis | C5: 협력업체 | D5: 대분류 | E5: 중분류 | F5: 규 격 | G5: 조출 | H5: 주간 | I5: 연장 | J5: 야간 | K5: 철야 | L5: Cum. T | M5: 조출 | N5: 주간 | O5: 연장 | P5: 야간 | Q5: 철야 | R5: Incr. T | S5: 조출 | T5: 주간 | U5: 연장 | V5: 야간 | W5: 철야 | X5: Cum. T
B6: =Cover!E18 -> UT | C6: =Cover!E16 -> M15X_PH4_041 | D6: 굴삭운반기계류 | E6: Back Hoe | F6: 2㎥ 미만 | G6: 0 | H6: 0 | I6: 0 | J6: 0 | K6: 0 | L6: 0 | M6: 0 | N6: 0 | O6: 0 | P6: 0 | Q6: 0 | R6: =SUM(M6:Q6) -> 0 | S6: =G6+M6 -> 0 | T6: =H6+N6 -> 0 | U6: =I6+O6 -> 0 | V6: =J6+P6 -> 0 | W6: =K6+Q6 -> 0 | X6: =SUM(S6:W6) -> 0
C7: =Cover!E20 -> 중원엔지니어링FAB | D7: 굴삭운반기계류 | E7: Back Hoe | F7: 2㎥ 이상~5㎥ 미만 | G7: 0 | H7: 0 | I7: 0 | J7: 0 | K7: 0 | L7: 0 | M7: 0 | N7: 0 | O7: 0 | P7: 0 | Q7: 0 | R7: =SUM(M7:Q7) -> 0 | S7: =G7+M7 -> 0 | T7: =H7+N7 -> 0 | U7: =I7+O7 -> 0 | V7: =J7+P7 -> 0 | W7: =K7+Q7 -> 0 | X7: =SUM(S7:W7) -> 0
D8: 굴삭운반기계류 | E8: Back Hoe | F8: 5㎥ 이상 ~ 10㎥ 미만 | G8: 0 | H8: 0 | I8: 0 | J8: 0 | K8: 0 | L8: 0 | M8: 0 | N8: 0 | O8: 0 | P8: 0 | Q8: 0 | R8: =SUM(M8:Q8) -> 0 | S8: =G8+M8 -> 0 | T8: =H8+N8 -> 0 | U8: =I8+O8 -> 0 | V8: =J8+P8 -> 0 | W8: =K8+Q8 -> 0 | X8: =SUM(S8:W8) -> 0
D9: 굴삭운반기계류 | E9: Back Hoe | F9: 10㎥ 이상 ~ 20㎥ 미만 | G9: 0 | H9: 0 | I9: 0 | J9: 0 | K9: 0 | L9: 0 | M9: 0 | N9: 0 | O9: 0 | P9: 0 | Q9: 0 | R9: =SUM(M9:Q9) -> 0 | S9: =G9+M9 -> 0 | T9: =H9+N9 -> 0 | U9: =I9+O9 -> 0 | V9: =J9+P9 -> 0 | W9: =K9+Q9 -> 0 | X9: =SUM(S9:W9) -> 0
D10: 굴삭운반기계류 | E10: 굴삭기 | F10: U.H.D | G10: 0 | H10: 0 | I10: 0 | J10: 0 | K10: 0 | L10: 0 | M10: 0 | N10: 0 | O10: 0 | P10: 0 | Q10: 0 | R10: =SUM(M10:Q10) -> 0 | S10: =G10+M10 -> 0 | T10: =H10+N10 -> 0 | U10: =I10+O10 -> 0 | V10: =J10+P10 -> 0 | W10: =K10+Q10 -> 0 | X10: =SUM(S10:W10) -> 0
D11: 굴삭운반기계류 | E11: 굴삭기 | F11: 0.2LC 이하 | G11: 0 | H11: 0 | I11: 0 | J11: 0 | K11: 0 | L11: 0 | M11: 0 | N11: 0 | O11: 0 | P11: 0 | Q11: 0 | R11: =SUM(M11:Q11) -> 0 | S11: =G11+M11 -> 0 | T11: =H11+N11 -> 0 | U11: =I11+O11 -> 0 | V11: =J11+P11 -> 0 | W11: =K11+Q11 -> 0 | X11: =SUM(S11:W11) -> 0
D12: 굴삭운반기계류 | E12: 굴삭기 | F12: 3LC | G12: 0 | H12: 0 | I12: 0 | J12: 0 | K12: 0 | L12: 0 | M12: 0 | N12: 0 | O12: 0 | P12: 0 | Q12: 0 | R12: =SUM(M12:Q12) -> 0 | S12: =G12+M12 -> 0 | T12: =H12+N12 -> 0 | U12: =I12+O12 -> 0 | V12: =J12+P12 -> 0 | W12: =K12+Q12 -> 0 | X12: =SUM(S12:W12) -> 0
D13: 굴삭운반기계류 | E13: 굴삭기 | F13: 6LC | G13: 0 | H13: 0 | I13: 0 | J13: 0 | K13: 0 | L13: 0 | M13: 0 | N13: 0 | O13: 0 | P13: 0 | Q13: 0 | R13: =SUM(M13:Q13) -> 0 | S13: =G13+M13 -> 0 | T13: =H13+N13 -> 0 | U13: =I13+O13 -> 0 | V13: =J13+P13 -> 0 | W13: =K13+Q13 -> 0 | X13: =SUM(S13:W13) -> 0
D14: 굴삭운반기계류 | E14: 굴삭기 | F14: 8LC | G14: 0 | H14: 0 | I14: 0 | J14: 0 | K14: 0 | L14: 0 | M14: 0 | N14: 0 | O14: 0 | P14: 0 | Q14: 0 | R14: =SUM(M14:Q14) -> 0 | S14: =G14+M14 -> 0 | T14: =H14+N14 -> 0 | U14: =I14+O14 -> 0 | V14: =J14+P14 -> 0 | W14: =K14+Q14 -> 0 | X14: =SUM(S14:W14) -> 0
D15: 고소작업장치류 | E15: 고소작업대 | F15: 굴절형 15M 이하 | G15: 0 | H15: 0 | I15: 0 | J15: 0 | K15: 0 | L15: 0 | M15: 0 | N15: 0 | O15: 0 | P15: 0 | Q15: 0 | R15: =SUM(M15:Q15) -> 0 | S15: =G15+M15 -> 0 | T15: =H15+N15 -> 0 | U15: =I15+O15 -> 0 | V15: =J15+P15 -> 0 | W15: =K15+Q15 -> 0 | X15: =SUM(S15:W15) -> 0
D16: 고소작업장치류 | E16: 고소작업대 | F16: 굴절형 15M 이상 | G16: 42 | H16: 280 | I16: 182 | J16: 0 | K16: 0 | L16: 504 | M16: 9 | N16: 28 | O16: 0 | P16: 0 | Q16: 0 | R16: =SUM(M16:Q16) -> 37 | S16: =G16+M16 -> 51 | T16: =H16+N16 -> 308 | U16: =I16+O16 -> 182 | V16: =J16+P16 -> 0 | W16: =K16+Q16 -> 0 | X16: =SUM(S16:W16) -> 541
D17: 고소작업장치류 | E17: 고소작업대 | F17: 수직형 7M 이하 | G17: 0 | H17: 0 | I17: 0 | J17: 0 | K17: 0 | L17: 0 | M17: 0 | N17: 0 | O17: 0 | P17: 0 | Q17: 0 | R17: =SUM(M17:Q17) -> 0 | S17: =G17+M17 -> 0 | T17: =H17+N17 -> 0 | U17: =I17+O17 -> 0 | V17: =J17+P17 -> 0 | W17: =K17+Q17 -> 0 | X17: =SUM(S17:W17) -> 0
D18: 고소작업장치류 | E18: 고소작업대 | F18: 수직형 7M ~ 12M | G18: 0 | H18: 0 | I18: 0 | J18: 0 | K18: 0 | L18: 0 | M18: 0 | N18: 0 | O18: 0 | P18: 0 | Q18: 0 | R18: =SUM(M18:Q18) -> 0 | S18: =G18+M18 -> 0 | T18: =H18+N18 -> 0 | U18: =I18+O18 -> 0 | V18: =J18+P18 -> 0 | W18: =K18+Q18 -> 0 | X18: =SUM(S18:W18) -> 0
D19: 고소작업장치류 | E19: 고소작업대 | F19: 수직형 12M이상 | G19: 0 | H19: 0 | I19: 0 | J19: 0 | K19: 0 | L19: 0 | M19: 0 | N19: 0 | O19: 0 | P19: 0 | Q19: 0 | R19: =SUM(M19:Q19) -> 0 | S19: =G19+M19 -> 0 | T19: =H19+N19 -> 0 | U19: =I19+O19 -> 0 | V19: =J19+P19 -> 0 | W19: =K19+Q19 -> 0 | X19: =SUM(S19:W19) -> 0
... D53: 기타기계류 | E53: 용접기 | F53: 용접기 | G53: 0 | H53: 0 | I53: 0 | J53: 0 | K53: 0 | L53: 0 | M53: 0 | N53: 0 | O53: 0 | P53: 0 | Q53: 0 | R53: =SUM(M53:Q53) -> 0 | S53: =G53+M53 -> 0 | T53: =H53+N53 -> 0 | U53: =I53+O53 -> 0 | V53: =J53+P53 -> 0 | W53: =K53+Q53 -> 0 | X53: =SUM(S53:W53) -> 0
D54: 기타 기계류 | E54: Bobcat | F54: Bobcat | M54: 0 | N54: 0 | O54: 0 | P54: 0 | Q54: 0 | R54: =SUM(M54:Q54) -> 0 | S54: =G54+M54 -> 0 | T54: =H54+N54 -> 0 | U54: =I54+O54 -> 0 | V54: =J54+P54 -> 0 | W54: =K54+Q54 -> 0 | X54: =SUM(S54:W54) -> 0
D55: 기타 기계류 | E55: 살수차 | F55: 살수차 | M55: 0 | N55: 0 | O55: 0 | P55: 0 | Q55: 0 | R55: =SUM(M55:Q55) -> 0 | S55: =G55+M55 -> 0 | T55: =H55+N55 -> 0 | U55: =I55+O55 -> 0 | V55: =J55+P55 -> 0 | W55: =K55+Q55 -> 0 | X55: =SUM(S55:W55) -> 0
D56: 기타 기계류 | E56: 공기압축기 | F56: 25.5㎥/min | G56: 0 | H56: 0 | I56: 0 | J56: 0 | K56: 0 | L56: 0 | M56: 0 | N56: 0 | O56: 0 | P56: 0 | Q56: 0 | R56: =SUM(M56:Q56) -> 0 | S56: =G56+M56 -> 0 | T56: =H56+N56 -> 0 | U56: =I56+O56 -> 0 | V56: =J56+P56 -> 0 | W56: =K56+Q56 -> 0 | X56: =SUM(S56:W56) -> 0
D57: 장비 52 | G57: 0 | H57: 0 | I57: 0 | J57: 0 | K57: 0 | L57: 0 | M57: 0 | N57: 0 | O57: 0 | P57: 0 | Q57: 0 | R57: =SUM(M57:Q57) -> 0 | S57: =G57+M57 -> 0 | T57: =H57+N57 -> 0 | U57: =I57+O57 -> 0 | V57: =J57+P57 -> 0 | W57: =K57+Q57 -> 0 | X57: =SUM(S57:W57) -> 0
D58: 장비 53 | G58: 0 | H58: 0 | I58: 0 | J58: 0 | K58: 0 | L58: 0 | M58: 0 | N58: 0 | O58: 0 | P58: 0 | Q58: 0 | R58: =SUM(M58:Q58) -> 0 | S58: =G58+M58 -> 0 | T58: =H58+N58 -> 0 | U58: =I58+O58 -> 0 | V58: =J58+P58 -> 0 | W58: =K58+Q58 -> 0 | X58: =SUM(S58:W58) -> 0
D59: 장비 54 | G59: 0 | H59: 0 | I59: 0 | J59: 0 | K59: 0 | L59: 0 | M59: 0 | N59: 0 | O59: 0 | P59: 0 | Q59: 0 | R59: =SUM(M59:Q59) -> 0 | S59: =G59+M59 -> 0 | T59: =H59+N59 -> 0 | U59: =I59+O59 -> 0 | V59: =J59+P59 -> 0 | W59: =K59+Q59 -> 0 | X59: =SUM(S59:W59) -> 0
D60: 장비 55 | G60: 0 | H60: 0 | I60: 0 | J60: 0 | K60: 0 | L60: 0 | M60: 0 | N60: 0 | O60: 0 | P60: 0 | Q60: 0 | R60: =SUM(M60:Q60) -> 0 | S60: =G60+M60 -> 0 | T60: =H60+N60 -> 0 | U60: =I60+O60 -> 0 | V60: =J60+P60 -> 0 | W60: =K60+Q60 -> 0 | X60: =SUM(S60:W60) -> 0
D61: 장비 56 | G61: 0 | H61: 0 | I61: 0 | J61: 0 | K61: 0 | L61: 0 | M61: 0 | N61: 0 | O61: 0 | P61: 0 | Q61: 0 | R61: =SUM(M61:Q61) -> 0 | S61: =G61+M61 -> 0 | T61: =H61+N61 -> 0 | U61: =I61+O61 -> 0 | V61: =J61+P61 -> 0 | W61: =K61+Q61 -> 0 | X61: =SUM(S61:W61) -> 0
D62: 장비 57 | G62: 0 | H62: 0 | I62: 0 | J62: 0 | K62: 0 | L62: 0 | M62: 0 | N62: 0 | O62: 0 | P62: 0 | Q62: 0 | R62: =SUM(M62:Q62) -> 0 | S62: =G62+M62 -> 0 | T62: =H62+N62 -> 0 | U62: =I62+O62 -> 0 | V62: =J62+P62 -> 0 | W62: =K62+Q62 -> 0 | X62: =SUM(S62:W62) -> 0
D63: 장비 58 | G63: 0 | H63: 0 | I63: 0 | J63: 0 | K63: 0 | L63: 0 | M63: 0 | N63: 0 | O63: 0 | P63: 0 | Q63: 0 | R63: =SUM(M63:Q63) -> 0 | S63: =G63+M63 -> 0 | T63: =H63+N63 -> 0 | U63: =I63+O63 -> 0 | V63: =J63+P63 -> 0 | W63: =K63+Q63 -> 0 | X63: =SUM(S63:W63) -> 0
D64: 장비 59 | G64: 0 | H64: 0 | I64: 0 | J64: 0 | K64: 0 | L64: 0 | M64: 0 | N64: 0 | O64: 0 | P64: 0 | Q64: 0 | R64: =SUM(M64:Q64) -> 0 | S64: =G64+M64 -> 0 | T64: =H64+N64 -> 0 | U64: =I64+O64 -> 0 | V64: =J64+P64 -> 0 | W64: =K64+Q64 -> 0 | X64: =SUM(S64:W64) -> 0
D65: 장비 60 | G65: 0 | H65: 0 | I65: 0 | J65: 0 | K65: 0 | L65: 0 | M65: 0 | N65: 0 | O65: 0 | P65: 0 | Q65: 0 | R65: =SUM(M65:Q65) -> 0 | S65: =G65+M65 -> 0 | T65: =H65+N65 -> 0 | U65: =I65+O65 -> 0 | V65: =J65+P65 -> 0 | W65: =K65+Q65 -> 0 | X65: =SUM(S65:W65) -> 0
D66: 장비 61 | G66: 0 | H66: 0 | I66: 0 | J66: 0 | K66: 0 | L66: 0 | M66: 0 | N66: 0 | O66: 0 | P66: 0 | Q66: 0 | R66: =SUM(M66:Q66) -> 0 | S66: =G66+M66 -> 0 | T66: =H66+N66 -> 0 | U66: =I66+O66 -> 0 | V66: =J66+P66 -> 0 | W66: =K66+Q66 -> 0 | X66: =SUM(S66:W66) -> 0
D67: 장비 62 | G67: 0 | H67: 0 | I67: 0 | J67: 0 | K67: 0 | L67: 0 | M67: 0 | N67: 0 | O67: 0 | P67: 0 | Q67: 0 | R67: =SUM(M67:Q67) -> 0 | S67: =G67+M67 -> 0 | T67: =H67+N67 -> 0 | U67: =I67+O67 -> 0 | V67: =J67+P67 -> 0 | W67: =K67+Q67 -> 0 | X67: =SUM(S67:W67) -> 0
D68: 장비 63 | G68: 0 | H68: 0 | I68: 0 | J68: 0 | K68: 0 | L68: 0 | M68: 0 | N68: 0 | O68: 0 | P68: 0 | Q68: 0 | R68: =SUM(M68:Q68) -> 0 | S68: =G68+M68 -> 0 | T68: =H68+N68 -> 0 | U68: =I68+O68 -> 0 | V68: =J68+P68 -> 0 | W68: =K68+Q68 -> 0 | X68: =SUM(S68:W68) -> 0
D69: 장비 64 | G69: 0 | H69: 0 | I69: 0 | J69: 0 | K69: 0 | L69: 0 | M69: 0 | N69: 0 | O69: 0 | P69: 0 | Q69: 0 | R69: =SUM(M69:Q69) -> 0 | S69: =G69+M69 -> 0 | T69: =H69+N69 -> 0 | U69: =I69+O69 -> 0 | V69: =J69+P69 -> 0 | W69: =K69+Q69 -> 0 | X69: =SUM(S69:W69) -> 0
D70: 장비 65 | G70: 0 | H70: 0 | I70: 0 | J70: 0 | K70: 0 | L70: =SUM(G70:K70) -> 0 | M70: 0 | N70: 0 | O70: 0 | P70: 0 | Q70: 0 | R70: =SUM(M70:Q70) -> 0 | S70: =G70+M70 -> 0 | T70: =H70+N70 -> 0 | U70: =I70+O70 -> 0 | V70: =J70+P70 -> 0 | W70: =K70+Q70 -> 0 | X70: =SUM(S70:W70) -> 0
D71: 장비 66 | G71: 0 | H71: 0 | I71: 0 | J71: 0 | K71: 0 | L71: =SUM(G71:K71) -> 0 | M71: 0 | N71: 0 | O71: 0 | P71: 0 | Q71: 0 | R71: =SUM(M71:Q71) -> 0 | S71: =G71+M71 -> 0 | T71: =H71+N71 -> 0 | U71: =I71+O71 -> 0 | V71: =J71+P71 -> 0 | W71: =K71+Q71 -> 0 | X71: =SUM(S71:W71) -> 0
D72: 장비 67 | G72: 0 | H72: 0 | I72: 0 | J72: 0 | K72: 0 | L72: =SUM(G72:K72) -> 0 | M72: 0 | N72: 0 | O72: 0 | P72: 0 | Q72: 0 | R72: =SUM(M72:Q72) -> 0 | S72: =G72+M72 -> 0 | T72: =H72+N72 -> 0 | U72: =I72+O72 -> 0 | V72: =J72+P72 -> 0 | W72: =K72+Q72 -> 0 | X72: =SUM(S72:W72) -> 0
D73: 장비 68 | G73: 0 | H73: 0 | I73: 0 | J73: 0 | K73: 0 | L73: =SUM(G73:K73) -> 0 | M73: 0 | N73: 0 | O73: 0 | P73: 0 | Q73: 0 | R73: =SUM(M73:Q73) -> 0 | S73: =G73+M73 -> 0 | T73: =H73+N73 -> 0 | U73: =I73+O73 -> 0 | V73: =J73+P73 -> 0 | W73: =K73+Q73 -> 0 | X73: =SUM(S73:W73) -> 0
...

Sheet 4.물량
B1: 4. 물량
B2: =CONCATENATE("금일 작업 현황 :",TEXT(Cover!E15," YYYY-MM-DD, aaaa")) -> 금일 작업 현황 : 2025-09-17, 수요일
B3: 구분 | C3: Zone | D3: 공종 | E3: BP사 | F3: Scope | G3: 대표물량_작업 내용 | H3: 단위 | I3: 총물량 | J3: 전일누적 | K3: 금일실적 | L3: 금일누적 | N3: 잔여 | P3: 작업 위치_코드 | Q3: 공종명 (Line명)
B4: PJT | D4: Dis | E4: 협력업체 | I4: [A] | J4: [B] | K4: [C] | L4: [D = B+C] | M4: F% : [D/A] | N4: [E = A-D] | O4: G% : [100% -F ] | Q4: 중공종명 (WBS 중공종) | R4: 소공종명 (WBS 소공종) | S4: 세공종명 (WBS 세공종)
B5: M15X PH4 | D5: =Cover!E18 -> UT | E5: =Cover!E16 -> M15X_PH4_041 | F5: F02 5F | G5: PCW 20 배관 공사 | H5: M | I5: 2178 | J5: 90 | K5: 30 | L5: =J5+K5 -> 120 | M5: =IFERROR(L5/I5,0) -> 0.055096419 | N5: =I5-L5 -> 2058 | O5: =IF(M5=0,0,IFERROR(100%-M5,0)) -> 0.94490358 | P5: =LEFT(F5,11)&"/"&LEFT(G5,10) -> F02 5F/PCW 20 배관 | Q5: PCW배관공사 | R5: PCW배관공사 | S5: A2-2. STS304 10S PIPING FOR 20℃ PCW
E6: =Cover!E20 -> 중원엔지니어링FAB | F6: F02 5F | G6: PCW 20(SCR) 배관 공사 | H6: M | I6: 2010 | K6: 0 | L6: =J6+K6 -> 0 | M6: =IFERROR(L6/I6,0) -> 0 | N6: =I6-L6 -> 2010 | O6: =IF(M6=0,0,IFERROR(100%-M6,0)) -> 0 | P6: =LEFT(F6,11)&"/"&LEFT(G6,10) -> F02 5F/PCW 20(SCR | Q6: PCW배관공사 | R6: PCW배관공사 | S6: A2-2. STS304 10S PIPING FOR 20℃ PCW
F7: F02 5F | G7: NPW 배관 공사 | H7: M | I7: 857 | J7: 0 | K7: 0 | L7: =J7+K7 -> 0 | M7: =IFERROR(L7/I7,0) -> 0 | N7: =I7-L7 -> 857 | O7: =IF(M7=0,0,IFERROR(100%-M7,0)) -> 0 | P7: =LEFT(F7,11)&"/"&LEFT(G7,10) -> F02 5F/NPW 배관 공사 | Q7: NPW배관공사 | R7: NPW배관공사 | S7: A2-3. STS304 10S PIPING FOR NPW
F8: F02 6F | G8: PCW 20 배관 공사 | H8: M | I8: 4591 | J8: 121 | K8: 30 | L8: =J8+K8 -> 151 | M8: =IFERROR(L8/I8,0) -> 0.032890438 | N8: =I8-L8 -> 4440 | O8: =IF(M8=0,0,IFERROR(100%-M8,0)) -> 0.96710956 | P8: =LEFT(F8,11)&"/"&LEFT(G8,10) -> F02 6F/PCW 20 배관 | Q8: PCW배관공사 | R8: PCW배관공사 | S8: A2-2. STS304 10S PIPING FOR 20℃ PCW
F9: F02 6F | G9: PCW 13 배관 공사 | H9: M | I9: 1256 | K9: 0 | L9: =J9+K9 -> 0 | M9: =IFERROR(L9/I9,0) -> 0 | N9: =I9-L9 -> 1256 | O9: =IF(M9=0,0,IFERROR(100%-M9,0)) -> 0 | P9: =LEFT(F9,11)&"/"&LEFT(G9,10) -> F02 6F/PCW 13 배관 | Q9: PCW배관공사 | R9: PCW배관공사 | S9: A2-1. STS304 10S PIPING FOR 13℃ PCW
F10: F02 6F | G10: NPW 배관 공사 | H10: M | I10: 861 | K10: 0 | L10: =J10+K10 -> 0 | M10: =IFERROR(L10/I10,0) -> 0 | N10: =I10-L10 -> 861 | O10: =IF(M10=0,0,IFERROR(100%-M10,0)) -> 0 | P10: =LEFT(F10,11)&"/"&LEFT(G10,10) -> F02 6F/NPW 배관 공사 | Q10: NPW배관공사 | R10: NPW배관공사 | S10: A2-3. STS304 10S PIPING FOR NPW
F11: F03 5F | G11: PCW 13 배관 공사 | H11: M | I11: 90 | J11: 0 | K11: 0 | L11: =J11+K11 -> 0 | M11: =IFERROR(L11/I11,0) -> 0 | N11: =I11-L11 -> 90 | O11: =IF(M11=0,0,IFERROR(100%-M11,0)) -> 0 | P11: =LEFT(F11,11)&"/"&LEFT(G11,10) -> F03 5F/PCW 13 배관 | Q11: PCW배관공사 | R11: PCW배관공사 | S11: A2-1. STS304 10S PIPING FOR 13℃ PCW
F12: F03 5F | G12: RO 배관 공사 | H12: M | I12: 26 | J12: 0 | K12: 0 | L12: =J12+K12 -> 0 | M12: =IFERROR(L12/I12,0) -> 0 | N12: =I12-L12 -> 26 | O12: =IF(M12=0,0,IFERROR(100%-M12,0)) -> 0 | P12: =LEFT(F12,11)&"/"&LEFT(G12,10) -> F03 5F/RO 배관 공사 | Q12: RO배관공사 | R12: RO배관공사 | S12: A2-4. STS304 10S PIPING FOR RO
F13: F03 6F | G13: PCW 20 배관 공사 | H13: M | I13: 487 | J13: 407 | L13: =J13+K13 -> 407 | M13: =IFERROR(L13/I13,0) -> 0.83572895 | N13: =I13-L13 -> 80 | O13: =IF(M13=0,0,IFERROR(100%-M13,0)) -> 0.16427105 | P13: =LEFT(F13,11)&"/"&LEFT(G13,10) -> F03 6F/PCW 20 배관 | Q13: PCW배관공사 | R13: PCW배관공사 | S13: A2-2. STS304 10S PIPING FOR 20℃ PCW
F14: F03 7F | G14: PCW 20 배관 공사 | H14: M | I14: 882 | J14: 350 | K14: 30 | L14: =J14+K14 -> 380 | M14: =IFERROR(L14/I14,0) -> 0.430839 | N14: =I14-L14 -> 502 | O14: =IF(M14=0,0,IFERROR(100%-M14,0)) -> 0.569161 | P14: =LEFT(F14,11)&"/"&LEFT(G14,10) -> F03 7F/PCW 20 배관 | Q14: PCW배관공사 | R14: PCW배관공사 | S14: A2-2. STS304 10S PIPING FOR 20℃ PCW
F15: F03 7F | G15: PCW 20(SCR) 배관 공사 | H15: M | I15: 162 | J15: 62 | K15: 0 | L15: =J15+K15 -> 62 | M15: =IFERROR(L15/I15,0) -> 0.38271605 | N15: =I15-L15 -> 100 | O15: =IF(M15=0,0,IFERROR(100%-M15,0)) -> 0.61728395 | P15: =LEFT(F15,11)&"/"&LEFT(G15,10) -> F03 7F/PCW 20(SCR | Q15: PCW배관공사 | R15: PCW배관공사 | S15: A2-2. STS304 10S PIPING FOR 20℃ PCW
F16: F03 7F | G16: NPW 배관 공사 | H16: M | I16: 80 | J16: 30 | L16: =J16+K16 -> 30 | M16: =IFERROR(L16/I16,0) -> 0.375 | N16: =I16-L16 -> 50 | O16: =IF(M16=0,0,IFERROR(100%-M16,0)) -> 0.625 | P16: =LEFT(F16,11)&"/"&LEFT(G16,10) -> F03 7F/NPW 배관 공사 | Q16: NPW배관공사 | R16: NPW배관공사 | S16: A2-3. STS304 10S PIPING FOR NPW
F17: F03 7F | G17: RO 배관 공사 | H17: M | I17: 70 | J17: 8 | L17: =J17+K17 -> 8 | M17: =IFERROR(L17/I17,0) -> 0.11428571 | N17: =I17-L17 -> 62 | O17: =IF(M17=0,0,IFERROR(100%-M17,0)) -> 0.88571429 | P17: =LEFT(F17,11)&"/"&LEFT(G17,10) -> F03 7F/RO 배관 공사 | Q17: RO배관공사 | R17: RO배관공사 | S17: A2-4. STS304 10S PIPING FOR RO
F18: F03 D/S | G18: PCW 20 배관 공사 | H18: M | I18: 24 | J18: 0 | K18: 0 | L18: =J18+K18 -> 0 | M18: =IFERROR(L18/I18,0) -> 0 | N18: =I18-L18 -> 24 | O18: =IF(M18=0,0,IFERROR(100%-M18,0)) -> 0 | P18: =LEFT(F18,11)&"/"&LEFT(G18,10) -> F03 D/S/PCW 20 배관 | Q18: PCW배관공사 | R18: PCW배관공사 | S18: A2-2. STS304 10S PIPING FOR 20℃ PCW
F19: F03 D/S | G19: PCW 20(SCR) 배관 공사 | H19: M | I19: 108 | J19: 0 | K19: 0 | L19: =J19+K19 -> 0 | M19: =IFERROR(L19/I19,0) -> 0 | N19: =I19-L19 -> 108 | O19: =IF(M19=0,0,IFERROR(100%-M19,0)) -> 0 | P19: =LEFT(F19,11)&"/"&LEFT(G19,10) -> F03 D/S/PCW 20(SCR | Q19: PCW배관공사 | R19: PCW배관공사 | S19: A2-2. STS304 10S PIPING FOR 20℃ PCW
F20: F03 D/S | G20: PCW 13 배관 공사 | H20: M | I20: 21 | J20: 0 | K20: 0 | L20: =J20+K20 -> 0 | M20: =IFERROR(L20/I20,0) -> 0 | N20: =I20-L20 -> 21 | O20: =IF(M20=0,0,IFERROR(100%-M20,0)) -> 0 | P20: =LEFT(F20,11)&"/"&LEFT(G20,10) -> F03 D/S/PCW 13 배관 | Q20: PCW배관공사 | R20: PCW배관공사 | S20: A2-1. STS304 10S PIPING FOR 13℃ PCW
F21: F03 D/S | G21: NPW 배관 공사 | H21: M | I21: 29 | J21: 0 | K21: 0 | L21: =J21+K21 -> 0 | M21: =IFERROR(L21/I21,0) -> 0 | N21: =I21-L21 -> 29 | O21: =IF(M21=0,0,IFERROR(100%-M21,0)) -> 0 | P21: =LEFT(F21,11)&"/"&LEFT(G21,10) -> F03 D/S/NPW 배관 공사 | Q21: NPW배관공사 | R21: NPW배관공사 | S21: A2-3. STS304 10S PIPING FOR NPW
F22: F03 D/S | G22: RO 배관 공사 | H22: M | I22: 10 | J22: 0 | K22: 0 | L22: =J22+K22 -> 0 | M22: =IFERROR(L22/I22,0) -> 0 | N22: =I22-L22 -> 10 | O22: =IF(M22=0,0,IFERROR(100%-M22,0)) -> 0 | P22: =LEFT(F22,11)&"/"&LEFT(G22,10) -> F03 D/S/RO 배관 공사 | Q22: RO배관공사 | R22: RO배관공사 | S22: A2-4. STS304 10S PIPING FOR RO
F23: F04 6F | G23: PCW 20 배관 공사 | H23: M | I23: 60 | J23: 0 | K23: 0 | L23: =J23+K23 -> 0 | M23: =IFERROR(L23/I23,0) -> 0 | N23: =I23-L23 -> 60 | O23: =IF(M23=0,0,IFERROR(100%-M23,0)) -> 0 | P23: =LEFT(F23,11)&"/"&LEFT(G23,10) -> F04 6F/PCW 20 배관 | Q23: PCW배관공사 | R23: PCW배관공사 | S23: A2-2. STS304 10S PIPING FOR 20℃ PCW
F24: F04 7F | G24: PCW 20 배관 공사 | H24: M | I24: 100 | J24: 0 | K24: 0 | L24: =J24+K24 -> 0 | M24: =IFERROR(L24/I24,0) -> 0 | N24: =I24-L24 -> 100 | O24: =IF(M24=0,0,IFERROR(100%-M24,0)) -> 0 | P24: =LEFT(F24,11)&"/"&LEFT(G24,10) -> F04 7F/PCW 20 배관 | Q24: PCW배관공사 | R24: PCW배관공사 | S24: A2-2. STS304 10S PIPING FOR 20℃ PCW
F25: F04 7F | G25: NPW 배관 공사 | H25: M | I25: 5 | J25: 0 | K25: 0 | L25: =J25+K25 -> 0 | M25: =IFERROR(L25/I25,0) -> 0 | N25: =I25-L25 -> 5 | O25: =IF(M25=0,0,IFERROR(100%-M25,0)) -> 0 | P25: =LEFT(F25,11)&"/"&LEFT(G25,10) -> F04 7F/NPW 배관 공사 | Q25: NPW배관공사 | R25: NPW배관공사 | S25: A2-3. STS304 10S PIPING FOR NPW
F26: F04 D/S | G26: PCW 20 배관 공사 | H26: M | I26: 10 | J26: 0 | K26: 0 | L26: =J26+K26 -> 0 | M26: =IFERROR(L26/I26,0) -> 0 | N26: =I26-L26 -> 10 | O26: =IF(M26=0,0,IFERROR(100%-M26,0)) -> 0 | P26: =LEFT(F26,11)&"/"&LEFT(G26,10) -> F04 D/S/PCW 20 배관 | Q26: PCW배관공사 | R26: PCW배관공사 | S26: A2-2. STS304 10S PIPING FOR 20℃ PCW
F27: F04 D/S | G27: NPW 배관 공사 | H27: M | I27: 10 | J27: 0 | K27: 0 | L27: =J27+K27 -> 0 | M27: =IFERROR(L27/I27,0) -> 0 | N27: =I27-L27 -> 10 | O27: =IF(M27=0,0,IFERROR(100%-M27,0)) -> 0 | P27: =LEFT(F27,11)&"/"&LEFT(G27,10) -> F04 D/S/NPW 배관 공사 | Q27: NPW배관공사 | R27: NPW배관공사 | S27: A2-3. STS304 10S PIPING FOR NPW
F28: CUB 1F | G28: RO 배관 공사 | H28: M | I28: 65 | J28: 0 | K28: 0 | L28: =J28+K28 -> 0 | M28: =IFERROR(L28/I28,0) -> 0 | N28: =I28-L28 -> 65 | O28: =IF(M28=0,0,IFERROR(100%-M28,0)) -> 0 | P28: =LEFT(F28,11)&"/"&LEFT(G28,10) -> CUB 1F/RO 배관 공사 | Q28: RO배관공사 | R28: RO배관공사 | S28: A2-4. STS304 10S PIPING FOR RO
F29: CUB 4F | G29: NPW 배관 공사 | H29: M | I29: 238 | J29: 0 | K29: 0 | L29: =J29+K29 -> 0 | M29: =IFERROR(L29/I29,0) -> 0 | N29: =I29-L29 -> 238 | O29: =IF(M29=0,0,IFERROR(100%-M29,0)) -> 0 | P29: =LEFT(F29,11)&"/"&LEFT(G29,10) -> CUB 4F/NPW 배관 공사 | Q29: NPW배관공사 | R29: NPW배관공사 | S29: A2-3. STS304 10S PIPING FOR NPW
... F37: CUB D/S | G37: RO 배관 공사 | H37: M | I37: 60 | J37: 15 | K37: 0 | L37: =J37+K37 -> 15 | M37: =IFERROR(L37/I37,0) -> 0.25 | N37: =I37-L37 -> 45 | O37: =IF(M37=0,0,IFERROR(100%-M37,0)) -> 0.75 | P37: =LEFT(F37,11)&"/"&LEFT(G37,10) -> CUB D/S/RO 배관 공사 | Q37: RO배관공사 | R37: RO배관공사 | S37: A2-4. STS304 10S PIPING FOR RO
J38: 0 | K38: 0 | L38: =J38+K38 -> 0 | M38: =IFERROR(L38/I38,0) -> 0 | N38: =I38-L38 -> 0 | O38: =IF(M38=0,0,IFERROR(100%-M38,0)) -> 0
J39: 0 | K39: 0 | L39: =J39+K39 -> 0 | M39: =IFERROR(L39/I39,0) -> 0 | N39: =I39-L39 -> 0 | O39: =IF(M39=0,0,IFERROR(100%-M39,0)) -> 0
K40: 0 | L40: =J40+K40 -> 0 | M40: =IFERROR(L40/I40,0) -> 0 | N40: =I40-L40 -> 0 | O40: =IF(M40=0,0,IFERROR(100%-M40,0)) -> 0
K41: 0 | L41: =J41+K41 -> 0 | M41: =IFERROR(L41/I41,0) -> 0 | N41: =I41-L41 -> 0 | O41: =IF(M41=0,0,IFERROR(100%-M41,0)) -> 0
J42: 0 | K42: 0 | L42: =J42+K42 -> 0 | M42: =IFERROR(L42/I42,0) -> 0 | N42: =I42-L42 -> 0 | O42: =IF(M42=0,0,IFERROR(100%-M42,0)) -> 0
J43: 0 | K43: 0 | L43: =J43+K43 -> 0 | M43: =IFERROR(L43/I43,0) -> 0 | N43: =I43-L43 -> 0 | O43: =IF(M43=0,0,IFERROR(100%-M43,0)) -> 0
J44: 0 | K44: 0 | L44: =J44+K44 -> 0 | M44: =IFERROR(L44/I44,0) -> 0 | N44: =I44-L44 -> 0 | O44: =IF(M44=0,0,IFERROR(100%-M44,0)) -> 0
J45: 0 | K45: 0 | L45: =J45+K45 -> 0 | M45: =IFERROR(L45/I45,0) -> 0 | N45: =I45-L45 -> 0 | O45: =IF(M45=0,0,IFERROR(100%-M45,0)) -> 0
J46: 0 | K46: 0 | L46: =J46+K46 -> 0 | M46: =IFERROR(L46/I46,0) -> 0 | N46: =I46-L46 -> 0 | O46: =IF(M46=0,0,IFERROR(100%-M46,0)) -> 0
J47: 0 | K47: 0 | L47: =J47+K47 -> 0 | M47: =IFERROR(L47/I47,0) -> 0 | N47: =I47-L47 -> 0 | O47: =IF(M47=0,0,IFERROR(100%-M47,0)) -> 0
...

Sheet 5.사진대지
B2: 5. 사진 대지
B3: PROJECT | C3: M15X PH4
B4: =Cover!E16 -> M15X_PH4_041 | C4: =Cover!E20 -> 중원엔지니어링FAB | I4: ='4.물량'!B2 -> 금일 작업 현황 : 2025-09-17, 수요일
B9: 일 자 | C9: =Cover!$E$15 -> 45917 | D9: 공 종 | E9: =Cover!$E$18 -> UT | F9: 위 치 | G9: 6F AIR PLENUM | H9: 일 자 | I9: =Cover!$E$15 -> 45917 | J9: 공 종 | K9: =Cover!$E$18 -> UT | L9: 위 치 | M9: 6F AIR PLENUM
B10: 작업 내용 | C10: 6F AIR PLENUM PCW20 배관 양중 | H10: 작업 내용 | I10: 6F AIR PLENUM PCW20 배관 양중
B15: 일 자 | C15: =Cover!$E$15 -> 45917 | D15: 공 종 | E15: =Cover!$E$18 -> UT | F15: 위 치 | G15: 6F CMP | H15: 일 자 | I15: =Cover!$E$15 -> 45917 | J15: 공 종 | K15: =Cover!$E$18 -> UT | L15: 위 치 | M15: 7F GANTRY
B16: 작업 내용 | C16: 6F CMP PCW20 배관 설치중 | H16: 작업 내용 | I16: 7F GANTRY 비계설치 작업
B21: 일 자 | C21: =Cover!$E$18 -> UT | D21: 공 종 | E21: =Cover!$E$18 -> UT | F21: 위 치 | G21: 3F~4F | H21: 일 자 | I21: =Cover!$E$18 -> UT | J21: 공 종 | K21: =Cover!$E$18 -> UT | L21: 위 치 | M21: 3F~4F
B22: 작업 내용 | H22: 작업 내용

Sheet 6.출력일보
A2: =REPLACE(CELL("filename",A1),1,FIND("]",CELL("filename",A1)),"") -> 6.출력일보 | C2: 일자 : | D2: =[1]Cover!E15 -> 45869
A3: NO | B3: 작업자 성함 | C3: 직종구분 | D3: 중공종명 (WBS 중공종) | E3: 소공종명 (WBS 소공종)2 | F3: 세공종명 (WBS 세공종) | G3: 작업 위치_코드 | H3: 금일 작업 사항 | I3: 조출 | J3: 주간 | K3: 연장 | L3: 야간 | M3: 철야 | N3: 비고 | Q3: 직종 | R3: =CONCATENATE("금일투입 [", TEXT(Cover!$E$15, "mm/dd"), "]") -> 금일투입 [09/17]
A4: 1 | B4: 정래혁 | C4: BP소장 | D4: 공통업무 | E4: 공통업무 | F4: 공통업무 | G4: F02 5F/PCW 20 배관 | H4: 현장 관리 감독 | I4: 1 | J4: 1 | Q4: [기능공] | R4: 조출 | S4: 주간 | T4: 연장 | U4: 야간 | V4: 철야 | W4: Incr. T
A5: =A4+1 -> 2 | B5: 김덕범 | C5: 공사관리자 | D5: 공통업무 | E5: 공통업무 | F5: 공통업무 | G5: F02 5F/PCW 20 배관 | H5: 현장 공사 관리 감독 | J5: 1 | Q5: ='2.직종별 인원현황'!F6 -> BP소장 | R5: =SUMIF(표2[[직종구분]:[작업 위치_코드]],$Q5,표2[조출]) -> 1 | S5: =SUMIF(표2[[직종구분]:[작업 위치_코드]],$Q5,표2[주간]) -> 1 | T5: =SUMIF(표2[[직종구분]:[작업 위치_코드]],$Q5,표2[연장]) -> 0 | U5: =SUMIF(표2[[직종구분]:[작업 위치_코드]],$Q5,표2[야간]) -> 0 | V5: =SUMIF(표2[[직종구분]:[작업 위치_코드]],$Q5,표2[철야]) -> 0 | W5: =SUM(R5:V5) -> 2
A6: =A5+1 -> 3 | B6: 김성덕 | C6: 공사관리자 | D6: 공통업무 | E6: 공통업무 | F6: 공통업무 | G6: F02 5F/PCW 20 배관 | H6: 현장 공사 관리 감독 | J6: 1 | Q6: ='2.직종별 인원현황'!F7 -> 공사관리자 | R6: =SUMIF(표2[[직종구분]:[작업 위치_코드]],$Q6,표2[조출]) -> 1 | S6: =SUMIF(표2[[직종구분]:[작업 위치_코드]],$Q6,표2[주간]) -> 5 | T6: =SUMIF(표2[[직종구분]:[작업 위치_코드]],$Q6,표2[연장]) -> 0 | U6: =SUMIF(표2[[직종구분]:[작업 위치_코드]],$Q6,표2[야간]) -> 0 | V6: =SUMIF(표2[[직종구분]:[작업 위치_코드]],$Q6,표2[철야]) -> 0 | W6: =SUM(R6:V6) -> 6
A7: =A6+1 -> 4 | B7: 권영우 | C7: 공사관리자 | D7: 공통업무 | E7: 공통업무 | F7: 공통업무 | G7: F02 5F/PCW 20 배관 | H7: 현장 공사 관리 감독 | J7: 1 | Q7: ='2.직종별 인원현황'!F8 -> 안전관리자 | R7: =SUMIF(표2[[직종구분]:[작업 위치_코드]],$Q7,표2[조출]) -> 2 | S7: =SUMIF(표2[[직종구분]:[작업 위치_코드]],$Q7,표2[주간]) -> 7 | T7: =SUMIF(표2[[직종구분]:[작업 위치_코드]],$Q7,표2[연장]) -> 0 | U7: =SUMIF(표2[[직종구분]:[작업 위치_코드]],$Q7,표2[야간]) -> 0 | V7: =SUMIF(표2[[직종구분]:[작업 위치_코드]],$Q7,표2[철야]) -> 0 | W7: =SUM(R7:V7) -> 9
A8: =A7+1 -> 5 | B8: 김동한 | C8: 공사관리자 | D8: 공통업무 | E8: 공통업무 | F8: 공통업무 | G8: F02 5F/PCW 20 배관 | H8: 현장 공사 관리 감독 | J8: 1 | Q8: ='2.직종별 인원현황'!F9 -> 품질관리자 | R8: =SUMIF(표2[[직종구분]:[작업 위치_코드]],$Q8,표2[조출]) -> 0 | S8: =SUMIF(표2[[직종구분]:[작업 위치_코드]],$Q8,표2[주간]) -> 4 | T8: =SUMIF(표2[[직종구분]:[작업 위치_코드]],$Q8,표2[연장]) -> 0 | U8: =SUMIF(표2[[직종구분]:[작업 위치_코드]],$Q8,표2[야간]) -> 0 | V8: =SUMIF(표2[[직종구분]:[작업 위치_코드]],$Q8,표2[철야]) -> 0 | W8: =SUM(R8:V8) -> 4
A9: =A8+1 -> 6 | B9: 김상대 | C9: 공사관리자 | D9: 공통업무 | E9: 공통업무 | F9: 공통업무 | G9: F03 6F/PCW 20 배관 | H9: 현장 공사 관리 감독 | I9: 1 | J9: 1 | Q9: ='2.직종별 인원현황'!F10 -> 일반관리자 | R9: =SUMIF(표2[[직종구분]:[작업 위치_코드]],$Q9,표2[조출]) -> 0 | S9: =SUMIF(표2[[직종구분]:[작업 위치_코드]],$Q9,표2[주간]) -> 0 | T9: =SUMIF(표2[[직종구분]:[작업 위치_코드]],$Q9,표2[연장]) -> 0 | U9: =SUMIF(표2[[직종구분]:[작업 위치_코드]],$Q9,표2[야간]) -> 0 | V9: =SUMIF(표2[[직종구분]:[작업 위치_코드]],$Q9,표2[철야]) -> 0 | W9: =SUM(R9:V9) -> 0
A10: =A9+1 -> 7 | B10: 허상봉 | C10: 안전관리자 | D10: 공통업무 | E10: 공통업무 | F10: 공통업무 | G10: F02 5F/PCW 20 배관 | H10: 현장 안전 관리 감독 | J10: 1 | Q10: ='2.직종별 인원현황'!F11 -> Shop설계 | R10: =SUMIF(표2[[직종구분]:[작업 위치_코드]],$Q10,표2[조출]) -> 0 | S10: =SUMIF(표2[[직종구분]:[작업 위치_코드]],$Q10,표2[주간]) -> 0 | T10: =SUMIF(표2[[직종구분]:[작업 위치_코드]],$Q10,표2[연장]) -> 0 | U10: =SUMIF(표2[[직종구분]:[작업 위치_코드]],$Q10,표2[야간]) -> 0 | V10: =SUMIF(표2[[직종구분]:[작업 위치_코드]],$Q10,표2[철야]) -> 0 | W10: =SUM(R10:V10) -> 0
A11: =A10+1 -> 8 | B11: 곽경록 | C11: 안전관리자 | D11: 공통업무 | E11: 공통업무 | F11: 공통업무 | G11: F02 5F/PCW 20 배관 | H11: 현장 안전 관리 감독 | J11: 1 | Q11: ='2.직종별 인원현황'!F12 -> 관리자07 | R11: =SUMIF(표2[[직종구분]:[작업 위치_코드]],$Q11,표2[조출]) -> 0 | S11: =SUMIF(표2[[직종구분]:[작업 위치_코드]],$Q11,표2[주간]) -> 0 | T11: =SUMIF(표2[[직종구분]:[작업 위치_코드]],$Q11,표2[연장]) -> 0 | U11: =SUMIF(표2[[직종구분]:[작업 위치_코드]],$Q11,표2[야간]) -> 0 | V11: =SUMIF(표2[[직종구분]:[작업 위치_코드]],$Q11,표2[철야]) -> 0 | W11: =SUM(R11:V11) -> 0
A12: =A11+1 -> 9 | B12: 장덕길 | C12: 안전관리자 | D12: 공통업무 | E12: 공통업무 | F12: 공통업무 | G12: F02 5F/PCW 20 배관 | H12: 현장 안전 관리 감독 | J12: 1 | Q12: ='2.직종별 인원현황'!F13 -> 관리자08 | R12: =SUMIF(표2[[직종구분]:[작업 위치_코드]],$Q12,표2[조출]) -> 0 | S12: =SUMIF(표2[[직종구분]:[작업 위치_코드]],$Q12,표2[주간]) -> 0 | T12: =SUMIF(표2[[직종구분]:[작업 위치_코드]],$Q12,표2[연장]) -> 0 | U12: =SUMIF(표2[[직종구분]:[작업 위치_코드]],$Q12,표2[야간]) -> 0 | V12: =SUMIF(표2[[직종구분]:[작업 위치_코드]],$Q12,표2[철야]) -> 0 | W12: =SUM(R12:V12) -> 0
A13: =A12+1 -> 10 | B13: 김연희 | C13: 안전관리자 | D13: 공통업무 | E13: 공통업무 | F13: 공통업무 | G13: F02 5F/PCW 20 배관 | H13: 현장 안전 관리 감독 | J13: 1 | Q13: ='2.직종별 인원현황'!F14 -> 관리자09 | R13: =SUMIF(표2[[직종구분]:[작업 위치_코드]],$Q13,표2[조출]) -> 0 | S13: =SUMIF(표2[[직종구분]:[작업 위치_코드]],$Q13,표2[주간]) -> 0 | T13: =SUMIF(표2[[직종구분]:[작업 위치_코드]],$Q13,표2[연장]) -> 0 | U13: =SUMIF(표2[[직종구분]:[작업 위치_코드]],$Q13,표2[야간]) -> 0 | V13: =SUMIF(표2[[직종구분]:[작업 위치_코드]],$Q13,표2[철야]) -> 0 | W13: =SUM(R13:V13) -> 0
A14: =A13+1 -> 11 | B14: 김헌 | C14: 안전관리자 | D14: 공통업무 | E14: 공통업무 | F14: 공통업무 | G14: F02 5F/PCW 20 배관 | H14: 현장 안전 관리 감독 | J14: 1 | Q14: ='2.직종별 인원현황'!F15 -> 관리자10 | R14: =SUMIF(표2[[직종구분]:[작업 위치_코드]],$Q14,표2[조출]) -> 0 | S14: =SUMIF(표2[[직종구분]:[작업 위치_코드]],$Q14,표2[주간]) -> 0 | T14: =SUMIF(표2[[직종구분]:[작업 위치_코드]],$Q14,표2[연장]) -> 0 | U14: =SUMIF(표2[[직종구분]:[작업 위치_코드]],$Q14,표2[야간]) -> 0 | V14: =SUMIF(표2[[직종구분]:[작업 위치_코드]],$Q14,표2[철야]) -> 0 | W14: =SUM(R14:V14) -> 0
A15: =A14+1 -> 12 | B15: 조성진 | C15: 안전관리자 | D15: 공통업무 | E15: 공통업무 | F15: 공통업무 | G15: F03 6F/PCW 20 배관 | H15: 현장 안전 관리 감독 | I15: 1 | J15: 1 | Q15: ='2.직종별 인원현황'!F16 -> H/C 장비기사 | R15: =SUMIF(표2[[직종구분]:[작업 위치_코드]],$Q15,표2[조출]) -> 0 | S15: =SUMIF(표2[[직종구분]:[작업 위치_코드]],$Q15,표2[주간]) -> 0 | T15: =SUMIF(표2[[직종구분]:[작업 위치_코드]],$Q15,표2[연장]) -> 0 | U15: =SUMIF(표2[[직종구분]:[작업 위치_코드]],$Q15,표2[야간]) -> 0 | V15: =SUMIF(표2[[직종구분]:[작업 위치_코드]],$Q15,표2[철야]) -> 0 | W15: =SUM(R15:V15) -> 0
A16: =A15+1 -> 13 | B16: 최윤석 | C16: 안전관리자 | D16: 공통업무 | E16: 공통업무 | F16: 공통업무 | G16: F03 6F/PCW 20 배관 | H16: 현장 안전 관리 감독 | I16: 1 | J16: 1 | Q16: ='2.직종별 인원현황'!F17 -> T/C 장비기사 | R16: =SUMIF(표2[[직종구분]:[작업 위치_코드]],$Q16,표2[조출]) -> 0 | S16: =SUMIF(표2[[직종구분]:[작업 위치_코드]],$Q16,표2[주간]) -> 0 | T16: =SUMIF(표2[[직종구분]:[작업 위치_코드]],$Q16,표2[연장]) -> 0 | U16: =SUMIF(표2[[직종구분]:[작업 위치_코드]],$Q16,표2[야간]) -> 0 | V16: =SUMIF(표2[[직종구분]:[작업 위치_코드]],$Q16,표2[철야]) -> 0 | W16: =SUM(R16:V16) -> 0
A17: =A16+1 -> 14 | B17: 최윤성 | C17: 품질관리자 | D17: 공통업무 | E17: 공통업무 | F17: 공통업무 | G17: F02 5F/PCW 20 배관 | H17: 현장 품질 관리 감독 | J17: 1 | Q17: ='2.직종별 인원현황'!F18 -> T/C 정비기사 | R17: =SUMIF(표2[[직종구분]:[작업 위치_코드]],$Q17,표2[조출]) -> 0 | S17: =SUMIF(표2[[직종구분]:[작업 위치_코드]],$Q17,표2[주간]) -> 0 | T17: =SUMIF(표2[[직종구분]:[작업 위치_코드]],$Q17,표2[연장]) -> 0 | U17: =SUMIF(표2[[직종구분]:[작업 위치_코드]],$Q17,표2[야간]) -> 0 | V17: =SUMIF(표2[[직종구분]:[작업 위치_코드]],$Q17,표2[철야]) -> 0 | W17: =SUM(R17:V17) -> 0
A18: =A17+1 -> 15 | B18: 윤재철 | C18: 품질관리자 | D18: 공통업무 | E18: 공통업무 | F18: 공통업무 | G18: F02 5F/PCW 20 배관 | H18: 현장 품질 관리 감독 | J18: 1 | Q18: ='2.직종별 인원현황'!F19 -> 스카이 장비기사 | R18: =SUMIF(표2[[직종구분]:[작업 위치_코드]],$Q18,표2[조출]) -> 0 | S18: =SUMIF(표2[[직종구분]:[작업 위치_코드]],$Q18,표2[주간]) -> 0 | T18: =SUMIF(표2[[직종구분]:[작업 위치_코드]],$Q18,표2[연장]) -> 0 | U18: =SUMIF(표2[[직종구분]:[작업 위치_코드]],$Q18,표2[야간]) -> 0 | V18: =SUMIF(표2[[직종구분]:[작업 위치_코드]],$Q18,표2[철야]) -> 0 | W18: =SUM(R18:V18) -> 0
A19: =A18+1 -> 16 | B19: 서준호 | C19: 품질관리자 | D19: 공통업무 | E19: 공통업무 | F19: 공통업무 | G19: F03 6F/PCW 20 배관 | H19: 현장 품질 관리 감독 | J19: 1 | Q19: ='2.직종별 인원현황'!F20 -> 지게차 장비기사 | R19: =SUMIF(표2[[직종구분]:[작업 위치_코드]],$Q19,표2[조출]) -> 0 | S19: =SUMIF(표2[[직종구분]:[작업 위치_코드]],$Q19,표2[주간]) -> 0 | T19: =SUMIF(표2[[직종구분]:[작업 위치_코드]],$Q19,표2[연장]) -> 0 | U19: =SUMIF(표2[[직종구분]:[작업 위치_코드]],$Q19,표2[야간]) -> 0 | V19: =SUMIF(표2[[직종구분]:[작업 위치_코드]],$Q19,표2[철야]) -> 0 | W19: =SUM(R19:V19) -> 0
A20: =A19+1 -> 17 | B20: 민영광 | C20: 품질관리자 | D20: 공통업무 | E20: 공통업무 | F20: 공통업무 | G20: F03 6F/PCW 20 배관 | H20: 현장 품질 관리 감독 | J20: 1 | Q20: ='2.직종별 인원현황'!F21 -> 펌프카 장비기사 | R20: =SUMIF(표2[[직종구분]:[작업 위치_코드]],$Q20,표2[조출]) -> 0 | S20: =SUMIF(표2[[직종구분]:[작업 위치_코드]],$Q20,표2[주간]) -> 0 | T20: =SUMIF(표2[[직종구분]:[작업 위치_코드]],$Q20,표2[연장]) -> 0 | U20: =SUMIF(표2[[직종구분]:[작업 위치_코드]],$Q20,표2[야간]) -> 0 | V20: =SUMIF(표2[[직종구분]:[작업 위치_코드]],$Q20,표2[철야]) -> 0 | W20: =SUM(R20:V20) -> 0
A21: =A20+1 -> 18 | B21: 임남수 | C21: 배관공 | D21: 공통업무 | E21: 공통업무 | F21: 공통업무 | G21: F03 6F/PCW 20 배관 | H21: 현장 공사 관리 감독 | I21: 1 | J21: 1 | Q21: ='2.직종별 인원현황'!F22 -> 기타 장비기사 | R21: =SUMIF(표2[[직종구분]:[작업 위치_코드]],$Q21,표2[조출]) -> 0 | S21: =SUMIF(표2[[직종구분]:[작업 위치_코드]],$Q21,표2[주간]) -> 0 | T21: =SUMIF(표2[[직종구분]:[작업 위치_코드]],$Q21,표2[연장]) -> 0 | U21: =SUMIF(표2[[직종구분]:[작업 위치_코드]],$Q21,표2[야간]) -> 0 | V21: =SUMIF(표2[[직종구분]:[작업 위치_코드]],$Q21,표2[철야]) -> 0 | W21: =SUM(R21:V21) -> 0
A22: =A21+1 -> 19 | B22: 이지훈 | C22: 배관공 | D22: 공통업무 | E22: 공통업무 | F22: 공통업무 | G22: F03 6F/PCW 20 배관 | H22: 현장 공사 관리 감독 | I22: 1 | J22: 1 | Q22: ='2.직종별 인원현황'!F23 -> PC조립공 | R22: =SUMIF(표2[[직종구분]:[작업 위치_코드]],$Q22,표2[조출]) -> 0 | S22: =SUMIF(표2[[직종구분]:[작업 위치_코드]],$Q22,표2[주간]) -> 0 | T22: =SUMIF(표2[[직종구분]:[작업 위치_코드]],$Q22,표2[연장]) -> 0 | U22: =SUMIF(표2[[직종구분]:[작업 위치_코드]],$Q22,표2[야간]) -> 0 | V22: =SUMIF(표2[[직종구분]:[작업 위치_코드]],$Q22,표2[철야]) -> 0 | W22: =SUM(R22:V22) -> 0
A23: =A22+1 -> 20 | B23: 옹민우 | C23: 배관공 | D23: 공통업무 | E23: 공통업무 | F23: 공통업무 | G23: F03 6F/PCW 20 배관 | H23: 현장 공사 관리 감독 | I23: 1 | J23: 1 | Q23: ='2.직종별 인원현황'!F24 -> PC후속공 | R23: =SUMIF(표2[[직종구분]:[작업 위치_코드]],$Q23,표2[조출]) -> 0 | S23: =SUMIF(표2[[직종구분]:[작업 위치_코드]],$Q23,표2[주간]) -> 0 | T23: =SUMIF(표2[[직종구분]:[작업 위치_코드]],$Q23,표2[연장]) -> 0 | U23: =SUMIF(표2[[직종구분]:[작업 위치_코드]],$Q23,표2[야간]) -> 0 | V23: =SUMIF(표2[[직종구분]:[작업 위치_코드]],$Q23,표2[철야]) -> 0 | W23: =SUM(R23:V23) -> 0
A24: =A23+1 -> 21 | B24: 성기현 | C24: 배관공 | D24: 공통업무 | E24: 공통업무 | F24: 공통업무 | G24: F03 6F/PCW 20 배관 | H24: 현장 공사 관리 감독 | I24: 1 | J24: 1 | Q24: ='2.직종별 인원현황'!F25 -> 가설펜스 | R24: =SUMIF(표2[[직종구분]:[작업 위치_코드]],$Q24,표2[조출]) -> 0 | S24: =SUMIF(표2[[직종구분]:[작업 위치_코드]],$Q24,표2[주간]) -> 0 | T24: =SUMIF(표2[[직종구분]:[작업 위치_코드]],$Q24,표2[연장]) -> 0 | U24: =SUMIF(표2[[직종구분]:[작업 위치_코드]],$Q24,표2[야간]) -> 0 | V24: =SUMIF(표2[[직종구분]:[작업 위치_코드]],$Q24,표2[철야]) -> 0 | W24: =SUM(R24:V24) -> 0
A25: =A24+1 -> 22 | B25: 김영섭 | C25: 보통인부 | D25: 공통업무 | E25: 공통업무 | F25: 공통업무 | G25: F03 6F/PCW 20 배관 | H25: 현장 공사 관리 감독 | I25: 1 | J25: 1 | Q25: ='2.직종별 인원현황'!F26 -> 견출공 | R25: =SUMIF(표2[[직종구분]:[작업 위치_코드]],$Q25,표2[조출]) -> 0 | S25: =SUMIF(표2[[직종구분]:[작업 위치_코드]],$Q25,표2[주간]) -> 0 | T25: =SUMIF(표2[[직종구분]:[작업 위치_코드]],$Q25,표2[연장]) -> 0 | U25: =SUMIF(표2[[직종구분]:[작업 위치_코드]],$Q25,표2[야간]) -> 0 | V25: =SUMIF(표2[[직종구분]:[작업 위치_코드]],$Q25,표2[철야]) -> 0 | W25: =SUM(R25:V25) -> 0
A26: =A25+1 -> 23 | B26: 박이노 | C26: 배관공 | D26: PCW배관공사 | E26: PCW배관공사 | F26: A2-2. STS304 10S PIPING FOR 20℃ PCW | G26: F03 7F/PCW 20 배관 | H26: 상부 PIPE 배열 및 용접,크롤라크레인 양중 | I26: 1 | J26: 1 | Q26: ='2.직종별 인원현황'!F27 -> 계장공 | R26: =SUMIF(표2[[직종구분]:[작업 위치_코드]],$Q26,표2[조출]) -> 0 | S26: =SUMIF(표2[[직종구분]:[작업 위치_코드]],$Q26,표2[주간]) -> 0 | T26: =SUMIF(표2[[직종구분]:[작업 위치_코드]],$Q26,표2[연장]) -> 0 | U26: =SUMIF(표2[[직종구분]:[작업 위치_코드]],$Q26,표2[야간]) -> 0 | V26: =SUMIF(표2[[직종구분]:[작업 위치_코드]],$Q26,표2[철야]) -> 0 | W26: =SUM(R26:V26) -> 0
A27: =A26+1 -> 24 | B27: 서준호 | C27: 배관공 | D27: PCW배관공사 | E27: PCW배관공사 | F27: A2-2. STS304 10S PIPING FOR 20℃ PCW | G27: F03 7F/PCW 20 배관 | H27: 상부 PIPE 배열 및 용접,크롤라크레인 양중 | I27: 1 | J27: 1 | Q27: ='2.직종별 인원현황'!F28 -> 관로공 | R27: =SUMIF(표2[[직종구분]:[작업 위치_코드]],$Q27,표2[조출]) -> 0 | S27: =SUMIF(표2[[직종구분]:[작업 위치_코드]],$Q27,표2[주간]) -> 0 | T27: =SUMIF(표2[[직종구분]:[작업 위치_코드]],$Q27,표2[연장]) -> 0 | U27: =SUMIF(표2[[직종구분]:[작업 위치_코드]],$Q27,표2[야간]) -> 0 | V27: =SUMIF(표2[[직종구분]:[작업 위치_코드]],$Q27,표2[철야]) -> 0 | W27: =SUM(R27:V27) -> 0
A28: =A27+1 -> 25 | B28: 정선혁 | C28: 용접공 | D28: PCW배관공사 | E28: PCW배관공사 | F28: A2-2. STS304 10S PIPING FOR 20℃ PCW | G28: F03 7F/PCW 20 배관 | H28: 상부 PIPE 배열 및 용접,크롤라크레인 양중 | I28: 1 | J28: 1 | Q28: ='2.직종별 인원현황'!F29 -> 교통통제 | R28: =SUMIF(표2[[직종구분]:[작업 위치_코드]],$Q28,표2[조출]) -> 0 | S28: =SUMIF(표2[[직종구분]:[작업 위치_코드]],$Q28,표2[주간]) -> 0 | T28: =SUMIF(표2[[직종구분]:[작업 위치_코드]],$Q28,표2[연장]) -> 0 | U28: =SUMIF(표2[[직종구분]:[작업 위치_코드]],$Q28,표2[야간]) -> 0 | V28: =SUMIF(표2[[직종구분]:[작업 위치_코드]],$Q28,표2[철야]) -> 0 | W28: =SUM(R28:V28) -> 0
A29: =A28+1 -> 26 | B29: 한기용 | C29: 용접공 | D29: PCW배관공사 | E29: PCW배관공사 | F29: A2-2. STS304 10S PIPING FOR 20℃ PCW | G29: F03 7F/PCW 20 배관 | H29: 상부 PIPE 배열 및 용접,크롤라크레인 양중 | I29: 1 | J29: 1 | Q29: ='2.직종별 인원현황'!F30 -> 기계 납품 설치 | R29: =SUMIF(표2[[직종구분]:[작업 위치_코드]],$Q29,표2[조출]) -> 0 | S29: =SUMIF(표2[[직종구분]:[작업 위치_코드]],$Q29,표2[주간]) -> 0 | T29: =SUMIF(표2[[직종구분]:[작업 위치_코드]],$Q29,표2[연장]) -> 0 | U29: =SUMIF(표2[[직종구분]:[작업 위치_코드]],$Q29,표2[야간]) -> 0 | V29: =SUMIF(표2[[직종구분]:[작업 위치_코드]],$Q29,표2[철야]) -> 0 | W29: =SUM(R29:V29) -> 0
A30: =A29+1 -> 27 | B30: 송민 | C30: 보통인부 | D30: PCW배관공사 | E30: PCW배관공사 | F30: A2-2. STS304 10S PIPING FOR 20℃ PCW | G30: F03 7F/PCW 20 배관 | H30: 상부 PIPE 배열 및 용접,크롤라크레인 양중 | I30: 1 | J30: 1 | Q30: ='2.직종별 인원현황'!F31 -> 덕트공 | R30: =SUMIF(표2[[직종구분]:[작업 위치_코드]],$Q30,표2[조출]) -> 0 | S30: =SUMIF(표2[[직종구분]:[작업 위치_코드]],$Q30,표2[주간]) -> 0 | T30: =SUMIF(표2[[직종구분]:[작업 위치_코드]],$Q30,표2[연장]) -> 0 | U30: =SUMIF(표2[[직종구분]:[작업 위치_코드]],$Q30,표2[야간]) -> 0 | V30: =SUMIF(표2[[직종구분]:[작업 위치_코드]],$Q30,표2[철야]) -> 0 | W30: =SUM(R30:V30) -> 0
A31: =A30+1 -> 28 | B31: 박강훈 | C31: 보통인부 | D31: PCW배관공사 | E31: PCW배관공사 | F31: A2-2. STS304 10S PIPING FOR 20℃ PCW | G31: F03 7F/PCW 20 배관 | H31: 상부 PIPE 배열 및 용접,크롤라크레인 양중 | I31: 1 | J31: 1 | Q31: ='2.직종별 인원현황'!F32 -> 데크공 | R31: =SUMIF(표2[[직종구분]:[작업 위치_코드]],$Q31,표2[조출]) -> 0 | S31: =SUMIF(표2[[직종구분]:[작업 위치_코드]],$Q31,표2[주간]) -> 0 | T31: =SUMIF(표2[[직종구분]:[작업 위치_코드]],$Q31,표2[연장]) -> 0 | U31: =SUMIF(표2[[직종구분]:[작업 위치_코드]],$Q31,표2[야간]) -> 0 | V31: =SUMIF(표2[[직종구분]:[작업 위치_코드]],$Q31,표2[철야]) -> 0 | W31: =SUM(R31:V31) -> 0
A32: =A31+1 -> 29 | B32: 이혜선 | C32: 화기감시자 | D32: PCW배관공사 | E32: PCW배관공사 | F32: A2-2. STS304 10S PIPING FOR 20℃ PCW | G32: F03 7F/PCW 20 배관 | H32: 상부 PIPE 배열 및 용접,크롤라크레인 양중 | I32: 1 | J32: 1 | Q32: ='2.직종별 인원현황'!F33 -> 도장공 | R32: =SUMIF(표2[[직종구분]:[작업 위치_코드]],$Q32,표2[조출]) -> 0 | S32: =SUMIF(표2[[직종구분]:[작업 위치_코드]],$Q32,표2[주간]) -> 0 | T32: =SUMIF(표2[[직종구분]:[작업 위치_코드]],$Q32,표2[연장]) -> 0 | U32: =SUMIF(표2[[직종구분]:[작업 위치_코드]],$Q32,표2[야간]) -> 0 | V32: =SUMIF(표2[[직종구분]:[작업 위치_코드]],$Q32,표2[철야]) -> 0 | W32: =SUM(R32:V32) -> 0
... A65: =A64+1 -> 62 | B65: 손문조 | C65: 유도원 | D65: PCW배관공사 | E65: PCW배관공사 | F65: A2-2. STS304 10S PIPING FOR 20℃ PCW | G65: F03 7F/PCW 20 배관 | H65: 상부 PIPE 배열 및 용접,크롤라크레인 양중 | I65: 1 | J65: 1 | Q65: ='2.직종별 인원현황'!F66 -> A/F Post 설치 | R65: =SUMIF(표2[[직종구분]:[작업 위치_코드]],$Q65,표2[조출]) -> 0 | S65: =SUMIF(표2[[직종구분]:[작업 위치_코드]],$Q65,표2[주간]) -> 0 | T65: =SUMIF(표2[[직종구분]:[작업 위치_코드]],$Q65,표2[연장]) -> 0 | U65: =SUMIF(표2[[직종구분]:[작업 위치_코드]],$Q65,표2[야간]) -> 0 | V65: =SUMIF(표2[[직종구분]:[작업 위치_코드]],$Q65,표2[철야]) -> 0 | W65: =SUM(R65:V65) -> 0
A66: =A65+1 -> 63 | B66: 송동우 | C66: 비계공 | D66: PCW배관공사 | E66: PCW배관공사 | F66: A2-2. STS304 10S PIPING FOR 20℃ PCW | G66: CUB 7F/PCW 20 배관 | H66: 7F X35,Y14/겐트리 비계수정,설치 | J66: 1 | Q66: ='2.직종별 인원현황'!F67 -> Access Floor | R66: =SUMIF(표2[[직종구분]:[작업 위치_코드]],$Q66,표2[조출]) -> 0 | S66: =SUMIF(표2[[직종구분]:[작업 위치_코드]],$Q66,표2[주간]) -> 0 | T66: =SUMIF(표2[[직종구분]:[작업 위치_코드]],$Q66,표2[연장]) -> 0 | U66: =SUMIF(표2[[직종구분]:[작업 위치_코드]],$Q66,표2[야간]) -> 0 | V66: =SUMIF(표2[[직종구분]:[작업 위치_코드]],$Q66,표2[철야]) -> 0 | W66: =SUM(R66:V66) -> 0
A67: =A66+1 -> 64 | B67: 조완준 | C67: 비계공 | D67: PCW배관공사 | E67: PCW배관공사 | F67: A2-2. STS304 10S PIPING FOR 20℃ PCW | G67: CUB 7F/PCW 20 배관 | H67: 7F X35,Y14/겐트리 비계수정,설치 | J67: 1 | Q67: ='2.직종별 인원현황'!F68 -> S/C M16 Bolt 설치 | R67: =SUMIF(표2[[직종구분]:[작업 위치_코드]],$Q67,표2[조출]) -> 0 | S67: =SUMIF(표2[[직종구분]:[작업 위치_코드]],$Q67,표2[주간]) -> 0 | T67: =SUMIF(표2[[직종구분]:[작업 위치_코드]],$Q67,표2[연장]) -> 0 | U67: =SUMIF(표2[[직종구분]:[작업 위치_코드]],$Q67,표2[야간]) -> 0 | V67: =SUMIF(표2[[직종구분]:[작업 위치_코드]],$Q67,표2[철야]) -> 0 | W67: =SUM(R67:V67) -> 0
A68: =A67+1 -> 65 | B68: 이성주 | C68: 비계공 | D68: PCW배관공사 | E68: PCW배관공사 | F68: A2-2. STS304 10S PIPING FOR 20℃ PCW | G68: CUB 7F/PCW 20 배관 | H68: 7F X35,Y14/겐트리 비계수정,설치 | J68: 1 | Q68: ='2.직종별 인원현황'!F69 -> S/C SQ Pipe 설치 | R68: =SUMIF(표2[[직종구분]:[작업 위치_코드]],$Q68,표2[조출]) -> 0 | S68: =SUMIF(표2[[직종구분]:[작업 위치_코드]],$Q68,표2[주간]) -> 0 | T68: =SUMIF(표2[[직종구분]:[작업 위치_코드]],$Q68,표2[연장]) -> 0 | U68: =SUMIF(표2[[직종구분]:[작업 위치_코드]],$Q68,표2[야간]) -> 0 | V68: =SUMIF(표2[[직종구분]:[작업 위치_코드]],$Q68,표2[철야]) -> 0 | W68: =SUM(R68:V68) -> 0
A69: =A68+1 -> 66 | B69: 김수 | C69: 비계공 | D69: PCW배관공사 | E69: PCW배관공사 | F69: A2-2. STS304 10S PIPING FOR 20℃ PCW | G69: CUB 7F/PCW 20 배관 | H69: 7F X35,Y14/겐트리 비계수정,설치 | J69: 1 | Q69: ='2.직종별 인원현황'!F70 -> S/C M8/Mould Bar 설치 | R69: =SUMIF(표2[[직종구분]:[작업 위치_코드]],$Q69,표2[조출]) -> 0 | S69: =SUMIF(표2[[직종구분]:[작업 위치_코드]],$Q69,표2[주간]) -> 0 | T69: =SUMIF(표2[[직종구분]:[작업 위치_코드]],$Q69,표2[연장]) -> 0 | U69: =SUMIF(표2[[직종구분]:[작업 위치_코드]],$Q69,표2[야간]) -> 0 | V69: =SUMIF(표2[[직종구분]:[작업 위치_코드]],$Q69,표2[철야]) -> 0 | W69: =SUM(R69:V69) -> 0
A70: =A69+1 -> 67 | B70: 이상무 | C70: 비계공 | D70: PCW배관공사 | E70: PCW배관공사 | F70: A2-2. STS304 10S PIPING FOR 20℃ PCW | G70: CUB 7F/PCW 20 배관 | H70: 7F X35,Y14/겐트리 비계수정,설치 | J70: 1 | Q70: ='2.직종별 인원현황'!F71 -> S/C Blind Panel 설치 | R70: =SUMIF(표2[[직종구분]:[작업 위치_코드]],$Q70,표2[조출]) -> 0 | S70: =SUMIF(표2[[직종구분]:[작업 위치_코드]],$Q70,표2[주간]) -> 0 | T70: =SUMIF(표2[[직종구분]:[작업 위치_코드]],$Q70,표2[연장]) -> 0 | U70: =SUMIF(표2[[직종구분]:[작업 위치_코드]],$Q70,표2[야간]) -> 0 | V70: =SUMIF(표2[[직종구분]:[작업 위치_코드]],$Q70,표2[철야]) -> 0 | W70: =SUM(R70:V70) -> 0
A71: =A70+1 -> 68 | B71: 김언기 | C71: 비계공 | D71: PCW배관공사 | E71: PCW배관공사 | F71: A2-2. STS304 10S PIPING FOR 20℃ PCW | G71: CUB 7F/PCW 20 배관 | H71: 7F X35,Y14/겐트리 비계수정,설치 | J71: 1 | Q71: ='2.직종별 인원현황'!F72 -> 케이블 포설 | R71: =SUMIF(표2[[직종구분]:[작업 위치_코드]],$Q71,표2[조출]) -> 0 | S71: =SUMIF(표2[[직종구분]:[작업 위치_코드]],$Q71,표2[주간]) -> 0 | T71: =SUMIF(표2[[직종구분]:[작업 위치_코드]],$Q71,표2[연장]) -> 0 | U71: =SUMIF(표2[[직종구분]:[작업 위치_코드]],$Q71,표2[야간]) -> 0 | V71: =SUMIF(표2[[직종구분]:[작업 위치_코드]],$Q71,표2[철야]) -> 0 | W71: =SUM(R71:V71) -> 0
A72: =A71+1 -> 69 | B72: 송진태 | C72: 비계공 | D72: PCW배관공사 | E72: PCW배관공사 | F72: A2-2. STS304 10S PIPING FOR 20℃ PCW | G72: CUB 7F/PCW 20 배관 | H72: 7F X35,Y14/겐트리 비계수정,설치 | J72: 1 | Q72: ='2.직종별 인원현황'!F73 -> 케이블 단말 | R72: =SUMIF(표2[[직종구분]:[작업 위치_코드]],$Q72,표2[조출]) -> 0 | S72: =SUMIF(표2[[직종구분]:[작업 위치_코드]],$Q72,표2[주간]) -> 0 | T72: =SUMIF(표2[[직종구분]:[작업 위치_코드]],$Q72,표2[연장]) -> 0 | U72: =SUMIF(표2[[직종구분]:[작업 위치_코드]],$Q72,표2[야간]) -> 0 | V72: =SUMIF(표2[[직종구분]:[작업 위치_코드]],$Q72,표2[철야]) -> 0 | W72: =SUM(R72:V72) -> 0
A73: =A72+1 -> 70 | B73: 유창 | C73: 비계공 | D73: PCW배관공사 | E73: PCW배관공사 | F73: A2-2. STS304 10S PIPING FOR 20℃ PCW | G73: CUB 7F/PCW 20 배관 | H73: 7F X35,Y14/겐트리 비계수정,설치 | J73: 1 | Q73: ='2.직종별 인원현황'!F74 -> Cable Tray 설치 | R73: =SUMIF(표2[[직종구분]:[작업 위치_코드]],$Q73,표2[조출]) -> 0 | S73: =SUMIF(표2[[직종구분]:[작업 위치_코드]],$Q73,표2[주간]) -> 0 | T73: =SUMIF(표2[[직종구분]:[작업 위치_코드]],$Q73,표2[연장]) -> 0 | U73: =SUMIF(표2[[직종구분]:[작업 위치_코드]],$Q73,표2[야간]) -> 0 | V73: =SUMIF(표2[[직종구분]:[작업 위치_코드]],$Q73,표2[철야]) -> 0 | W73: =SUM(R73:V73) -> 0
...

Sheet WBS
A2: 대공종 CODE | B2: 대공종명 | C2: 중공공 CODE | D2: 중공종명 | E2: 소공종 CODE | F2: 소공종명 | H2: 대공종명 | I2: 세공종명
B3: 설비 | D3: 공통업무 | F3: 공통업무 | H3: 설비 | I3: 공통업무
A4: ME | B4: 설비 | C4: 01 | D4: 일반공조설비공사 | E4: 010 | F4: 장비설치공사 | H4: 설비 | I4: 010101 장비설치공사
A5: ME | B5: 설비 | C5: 01 | D5: 일반공조설비공사 | E5: 020 | F5: 온수배관공사 | H5: 설비 | I5: 010102010101 B1F 증기배관공사
A6: ME | B6: 설비 | C6: 01 | D6: 일반공조설비공사 | E6: 030 | F6: 드레인배관공사 | H6: 설비 | I6: 010102010102 1F 증기배관공사
A7: ME | B7: 설비 | C7: 01 | D7: 일반공조설비공사 | E7: 040 | F7: 덕트드레인배관공사 | H7: 설비 | I7: 010102010103 2F 증기배관공사
A8: ME | B8: 설비 | C8: 01 | D8: 일반공조설비공사 | E8: 050 | F8: 폐열회수배관공사 | H8: 설비 | I8: 010102010104 3F 증기배관공사
A9: ME | B9: 설비 | C9: 01 | D9: 일반공조설비공사 | E9: 060 | F9: 공조덕트설치공사 | H9: 설비 | I9: 010102010105 4F 증기배관공사
